ERROR    2016-10-07 21:22:22,293 django.request      [line 124 ] Internal Server Error: /restapi/arch/appids/
Traceback (most recent call last):
  File "/data/fmc/pycharm_workspase/omni/.venv/lib/python2.7/site-packages/django/core/handlers/exception.py", line 39, in inner
    response = get_response(request)
  File "/data/fmc/pycharm_workspase/omni/.venv/lib/python2.7/site-packages/django/core/handlers/base.py", line 249, in _legacy_get_response
    response = self._get_response(request)
  File "/data/fmc/pycharm_workspase/omni/.venv/lib/python2.7/site-packages/django/core/handlers/base.py", line 187, in _get_response
    response = self.process_exception_by_middleware(e, request)
  File "/data/fmc/pycharm_workspase/omni/.venv/lib/python2.7/site-packages/django/core/handlers/base.py", line 185, in _get_response
    response = wrapped_callback(request, *callback_args, **callback_kwargs)
  File "/data/fmc/pycharm_workspase/omni/.venv/lib/python2.7/site-packages/django/views/decorators/csrf.py", line 58, in wrapped_view
    return view_func(*args, **kwargs)
  File "/data/fmc/pycharm_workspase/omni/.venv/lib/python2.7/site-packages/django/views/generic/base.py", line 68, in view
    return self.dispatch(request, *args, **kwargs)
  File "/data/fmc/pycharm_workspase/omni/.venv/lib/python2.7/site-packages/rest_framework/views.py", line 474, in dispatch
    response = self.handle_exception(exc)
  File "/data/fmc/pycharm_workspase/omni/.venv/lib/python2.7/site-packages/rest_framework/views.py", line 434, in handle_exception
    self.raise_uncaught_exception(exc)
  File "/data/fmc/pycharm_workspase/omni/.venv/lib/python2.7/site-packages/rest_framework/views.py", line 471, in dispatch
    response = handler(request, *args, **kwargs)
  File "/data/fmc/pycharm_workspase/omni/.venv/lib/python2.7/site-packages/rest_framework/generics.py", line 200, in get
    return self.list(request, *args, **kwargs)
  File "/data/fmc/pycharm_workspase/omni/omni/libs/django/view/mixin.py", line 89, in list
    response_data = self.get_response_data(request, serializer)
  File "/data/fmc/pycharm_workspase/omni/omni/libs/django/view/mixin.py", line 94, in get_response_data
    raise ValueError(serializer.data)
  File "/data/fmc/pycharm_workspase/omni/.venv/lib/python2.7/site-packages/rest_framework/serializers.py", line 701, in data
    ret = super(ListSerializer, self).data
  File "/data/fmc/pycharm_workspase/omni/.venv/lib/python2.7/site-packages/rest_framework/serializers.py", line 240, in data
    self._data = self.to_representation(self.instance)
  File "/data/fmc/pycharm_workspase/omni/.venv/lib/python2.7/site-packages/rest_framework/serializers.py", line 619, in to_representation
    self.child.to_representation(item) for item in iterable
  File "/data/fmc/pycharm_workspase/omni/.venv/lib/python2.7/site-packages/rest_framework/serializers.py", line 464, in to_representation
    attribute = field.get_attribute(instance)
  File "/data/fmc/pycharm_workspase/omni/.venv/lib/python2.7/site-packages/rest_framework/relations.py", line 161, in get_attribute
    return get_attribute(instance, self.source_attrs)
  File "/data/fmc/pycharm_workspase/omni/.venv/lib/python2.7/site-packages/rest_framework/fields.py", line 81, in get_attribute
    instance = instance[attr]
KeyError: u'product'
ERROR    2016-10-07 21:23:16,474 django.request      [line 124 ] Internal Server Error: /restapi/arch/appids/
Traceback (most recent call last):
  File "/data/fmc/pycharm_workspase/omni/.venv/lib/python2.7/site-packages/django/core/handlers/exception.py", line 39, in inner
    response = get_response(request)
  File "/data/fmc/pycharm_workspase/omni/.venv/lib/python2.7/site-packages/django/core/handlers/base.py", line 249, in _legacy_get_response
    response = self._get_response(request)
  File "/data/fmc/pycharm_workspase/omni/.venv/lib/python2.7/site-packages/django/core/handlers/base.py", line 187, in _get_response
    response = self.process_exception_by_middleware(e, request)
  File "/data/fmc/pycharm_workspase/omni/.venv/lib/python2.7/site-packages/django/core/handlers/base.py", line 185, in _get_response
    response = wrapped_callback(request, *callback_args, **callback_kwargs)
  File "/data/fmc/pycharm_workspase/omni/.venv/lib/python2.7/site-packages/django/views/decorators/csrf.py", line 58, in wrapped_view
    return view_func(*args, **kwargs)
  File "/data/fmc/pycharm_workspase/omni/.venv/lib/python2.7/site-packages/django/views/generic/base.py", line 68, in view
    return self.dispatch(request, *args, **kwargs)
  File "/data/fmc/pycharm_workspase/omni/.venv/lib/python2.7/site-packages/rest_framework/views.py", line 474, in dispatch
    response = self.handle_exception(exc)
  File "/data/fmc/pycharm_workspase/omni/.venv/lib/python2.7/site-packages/rest_framework/views.py", line 434, in handle_exception
    self.raise_uncaught_exception(exc)
  File "/data/fmc/pycharm_workspase/omni/.venv/lib/python2.7/site-packages/rest_framework/views.py", line 471, in dispatch
    response = handler(request, *args, **kwargs)
  File "/data/fmc/pycharm_workspase/omni/.venv/lib/python2.7/site-packages/rest_framework/generics.py", line 200, in get
    return self.list(request, *args, **kwargs)
  File "/data/fmc/pycharm_workspase/omni/omni/libs/django/view/mixin.py", line 89, in list
    response_data = self.get_response_data(request, serializer)
  File "/data/fmc/pycharm_workspase/omni/omni/libs/django/view/mixin.py", line 95, in get_response_data
    response_data = self.clean_relation_fields(request, serializer.data)
  File "/data/fmc/pycharm_workspase/omni/.venv/lib/python2.7/site-packages/rest_framework/serializers.py", line 701, in data
    ret = super(ListSerializer, self).data
  File "/data/fmc/pycharm_workspase/omni/.venv/lib/python2.7/site-packages/rest_framework/serializers.py", line 240, in data
    self._data = self.to_representation(self.instance)
  File "/data/fmc/pycharm_workspase/omni/.venv/lib/python2.7/site-packages/rest_framework/serializers.py", line 619, in to_representation
    self.child.to_representation(item) for item in iterable
  File "/data/fmc/pycharm_workspase/omni/.venv/lib/python2.7/site-packages/rest_framework/serializers.py", line 464, in to_representation
    attribute = field.get_attribute(instance)
  File "/data/fmc/pycharm_workspase/omni/.venv/lib/python2.7/site-packages/rest_framework/relations.py", line 161, in get_attribute
    return get_attribute(instance, self.source_attrs)
  File "/data/fmc/pycharm_workspase/omni/.venv/lib/python2.7/site-packages/rest_framework/fields.py", line 81, in get_attribute
    instance = instance[attr]
KeyError: u'product'
WARNING  2016-10-07 22:33:52,379 django.request      [line 152 ] Not Found: /arch/appid
WARNING  2016-10-07 22:33:57,509 django.request      [line 152 ] Not Found: /arch/appid/list
WARNING  2016-10-07 22:34:41,418 django.request      [line 152 ] Not Found: /arch/appid/list
WARNING  2016-10-07 22:34:43,289 django.request      [line 152 ] Not Found: /arch/appid/list
WARNING  2016-10-07 22:34:44,546 django.request      [line 152 ] Not Found: /arch/appid/list
WARNING  2016-10-07 22:34:45,549 django.request      [line 152 ] Not Found: /arch/appid/list
WARNING  2016-10-07 22:34:46,465 django.request      [line 152 ] Not Found: /arch/appid/list
WARNING  2016-10-07 22:34:47,390 django.request      [line 152 ] Not Found: /arch/appid/list
WARNING  2016-10-07 22:34:48,390 django.request      [line 152 ] Not Found: /arch/appid/list
WARNING  2016-10-07 22:34:49,313 django.request      [line 152 ] Not Found: /arch/appid/list
ERROR    2016-10-07 22:34:56,264 django.request      [line 124 ] Internal Server Error: /arch/appid/list/
Traceback (most recent call last):
  File "/data/fmc/pycharm_workspase/omni/.venv/lib/python2.7/site-packages/django/core/handlers/exception.py", line 39, in inner
    response = get_response(request)
  File "/data/fmc/pycharm_workspase/omni/.venv/lib/python2.7/site-packages/django/core/handlers/base.py", line 249, in _legacy_get_response
    response = self._get_response(request)
  File "/data/fmc/pycharm_workspase/omni/.venv/lib/python2.7/site-packages/django/core/handlers/base.py", line 217, in _get_response
    response = self.process_exception_by_middleware(e, request)
  File "/data/fmc/pycharm_workspase/omni/.venv/lib/python2.7/site-packages/django/core/handlers/base.py", line 215, in _get_response
    response = response.render()
  File "/data/fmc/pycharm_workspase/omni/.venv/lib/python2.7/site-packages/django/template/response.py", line 109, in render
    self.content = self.rendered_content
  File "/data/fmc/pycharm_workspase/omni/.venv/lib/python2.7/site-packages/django/template/response.py", line 86, in rendered_content
    content = template.render(context, self._request)
  File "/data/fmc/pycharm_workspase/omni/.venv/lib/python2.7/site-packages/django/template/backends/django.py", line 66, in render
    return self.template.render(context)
  File "/data/fmc/pycharm_workspase/omni/.venv/lib/python2.7/site-packages/django/template/base.py", line 208, in render
    return self._render(context)
  File "/data/fmc/pycharm_workspase/omni/.venv/lib/python2.7/site-packages/django/template/base.py", line 199, in _render
    return self.nodelist.render(context)
  File "/data/fmc/pycharm_workspase/omni/.venv/lib/python2.7/site-packages/django/template/base.py", line 994, in render
    bit = node.render_annotated(context)
  File "/data/fmc/pycharm_workspase/omni/.venv/lib/python2.7/site-packages/django/template/base.py", line 961, in render_annotated
    return self.render(context)
  File "/data/fmc/pycharm_workspase/omni/.venv/lib/python2.7/site-packages/django/template/loader_tags.py", line 152, in render
    compiled_parent = self.get_parent(context)
  File "/data/fmc/pycharm_workspase/omni/.venv/lib/python2.7/site-packages/django/template/loader_tags.py", line 149, in get_parent
    return self.find_template(parent, context)
  File "/data/fmc/pycharm_workspase/omni/.venv/lib/python2.7/site-packages/django/template/loader_tags.py", line 129, in find_template
    template_name, skip=history,
  File "/data/fmc/pycharm_workspase/omni/.venv/lib/python2.7/site-packages/django/template/engine.py", line 134, in find_template
    name, template_dirs=dirs, skip=skip,
  File "/data/fmc/pycharm_workspase/omni/.venv/lib/python2.7/site-packages/django/template/loaders/base.py", line 44, in get_template
    contents, origin, origin.template_name, self.engine,
  File "/data/fmc/pycharm_workspase/omni/.venv/lib/python2.7/site-packages/django/template/base.py", line 191, in __init__
    self.nodelist = self.compile_nodelist()
  File "/data/fmc/pycharm_workspase/omni/.venv/lib/python2.7/site-packages/django/template/base.py", line 233, in compile_nodelist
    return parser.parse()
  File "/data/fmc/pycharm_workspase/omni/.venv/lib/python2.7/site-packages/django/template/base.py", line 518, in parse
    raise self.error(token, e)
TemplateSyntaxError: default requires 2 arguments, 1 provided
ERROR    2016-10-07 22:36:22,958 django.request      [line 124 ] Internal Server Error: /arch/appid/list/
Traceback (most recent call last):
  File "/data/fmc/pycharm_workspase/omni/.venv/lib/python2.7/site-packages/django/core/handlers/exception.py", line 39, in inner
    response = get_response(request)
  File "/data/fmc/pycharm_workspase/omni/.venv/lib/python2.7/site-packages/django/core/handlers/base.py", line 249, in _legacy_get_response
    response = self._get_response(request)
  File "/data/fmc/pycharm_workspase/omni/.venv/lib/python2.7/site-packages/django/core/handlers/base.py", line 217, in _get_response
    response = self.process_exception_by_middleware(e, request)
  File "/data/fmc/pycharm_workspase/omni/.venv/lib/python2.7/site-packages/django/core/handlers/base.py", line 215, in _get_response
    response = response.render()
  File "/data/fmc/pycharm_workspase/omni/.venv/lib/python2.7/site-packages/django/template/response.py", line 109, in render
    self.content = self.rendered_content
  File "/data/fmc/pycharm_workspase/omni/.venv/lib/python2.7/site-packages/django/template/response.py", line 86, in rendered_content
    content = template.render(context, self._request)
  File "/data/fmc/pycharm_workspase/omni/.venv/lib/python2.7/site-packages/django/template/backends/django.py", line 66, in render
    return self.template.render(context)
  File "/data/fmc/pycharm_workspase/omni/.venv/lib/python2.7/site-packages/django/template/base.py", line 208, in render
    return self._render(context)
  File "/data/fmc/pycharm_workspase/omni/.venv/lib/python2.7/site-packages/django/template/base.py", line 199, in _render
    return self.nodelist.render(context)
  File "/data/fmc/pycharm_workspase/omni/.venv/lib/python2.7/site-packages/django/template/base.py", line 994, in render
    bit = node.render_annotated(context)
  File "/data/fmc/pycharm_workspase/omni/.venv/lib/python2.7/site-packages/django/template/base.py", line 961, in render_annotated
    return self.render(context)
  File "/data/fmc/pycharm_workspase/omni/.venv/lib/python2.7/site-packages/django/template/loader_tags.py", line 152, in render
    compiled_parent = self.get_parent(context)
  File "/data/fmc/pycharm_workspase/omni/.venv/lib/python2.7/site-packages/django/template/loader_tags.py", line 149, in get_parent
    return self.find_template(parent, context)
  File "/data/fmc/pycharm_workspase/omni/.venv/lib/python2.7/site-packages/django/template/loader_tags.py", line 129, in find_template
    template_name, skip=history,
  File "/data/fmc/pycharm_workspase/omni/.venv/lib/python2.7/site-packages/django/template/engine.py", line 134, in find_template
    name, template_dirs=dirs, skip=skip,
  File "/data/fmc/pycharm_workspase/omni/.venv/lib/python2.7/site-packages/django/template/loaders/base.py", line 44, in get_template
    contents, origin, origin.template_name, self.engine,
  File "/data/fmc/pycharm_workspase/omni/.venv/lib/python2.7/site-packages/django/template/base.py", line 191, in __init__
    self.nodelist = self.compile_nodelist()
  File "/data/fmc/pycharm_workspase/omni/.venv/lib/python2.7/site-packages/django/template/base.py", line 233, in compile_nodelist
    return parser.parse()
  File "/data/fmc/pycharm_workspase/omni/.venv/lib/python2.7/site-packages/django/template/base.py", line 518, in parse
    raise self.error(token, e)
TemplateSyntaxError: default requires 2 arguments, 1 provided
ERROR    2016-10-07 22:36:25,071 django.request      [line 124 ] Internal Server Error: /arch/appid/list/
Traceback (most recent call last):
  File "/data/fmc/pycharm_workspase/omni/.venv/lib/python2.7/site-packages/django/core/handlers/exception.py", line 39, in inner
    response = get_response(request)
  File "/data/fmc/pycharm_workspase/omni/.venv/lib/python2.7/site-packages/django/core/handlers/base.py", line 249, in _legacy_get_response
    response = self._get_response(request)
  File "/data/fmc/pycharm_workspase/omni/.venv/lib/python2.7/site-packages/django/core/handlers/base.py", line 217, in _get_response
    response = self.process_exception_by_middleware(e, request)
  File "/data/fmc/pycharm_workspase/omni/.venv/lib/python2.7/site-packages/django/core/handlers/base.py", line 215, in _get_response
    response = response.render()
  File "/data/fmc/pycharm_workspase/omni/.venv/lib/python2.7/site-packages/django/template/response.py", line 109, in render
    self.content = self.rendered_content
  File "/data/fmc/pycharm_workspase/omni/.venv/lib/python2.7/site-packages/django/template/response.py", line 86, in rendered_content
    content = template.render(context, self._request)
  File "/data/fmc/pycharm_workspase/omni/.venv/lib/python2.7/site-packages/django/template/backends/django.py", line 66, in render
    return self.template.render(context)
  File "/data/fmc/pycharm_workspase/omni/.venv/lib/python2.7/site-packages/django/template/base.py", line 208, in render
    return self._render(context)
  File "/data/fmc/pycharm_workspase/omni/.venv/lib/python2.7/site-packages/django/template/base.py", line 199, in _render
    return self.nodelist.render(context)
  File "/data/fmc/pycharm_workspase/omni/.venv/lib/python2.7/site-packages/django/template/base.py", line 994, in render
    bit = node.render_annotated(context)
  File "/data/fmc/pycharm_workspase/omni/.venv/lib/python2.7/site-packages/django/template/base.py", line 961, in render_annotated
    return self.render(context)
  File "/data/fmc/pycharm_workspase/omni/.venv/lib/python2.7/site-packages/django/template/loader_tags.py", line 152, in render
    compiled_parent = self.get_parent(context)
  File "/data/fmc/pycharm_workspase/omni/.venv/lib/python2.7/site-packages/django/template/loader_tags.py", line 149, in get_parent
    return self.find_template(parent, context)
  File "/data/fmc/pycharm_workspase/omni/.venv/lib/python2.7/site-packages/django/template/loader_tags.py", line 129, in find_template
    template_name, skip=history,
  File "/data/fmc/pycharm_workspase/omni/.venv/lib/python2.7/site-packages/django/template/engine.py", line 134, in find_template
    name, template_dirs=dirs, skip=skip,
  File "/data/fmc/pycharm_workspase/omni/.venv/lib/python2.7/site-packages/django/template/loaders/base.py", line 44, in get_template
    contents, origin, origin.template_name, self.engine,
  File "/data/fmc/pycharm_workspase/omni/.venv/lib/python2.7/site-packages/django/template/base.py", line 191, in __init__
    self.nodelist = self.compile_nodelist()
  File "/data/fmc/pycharm_workspase/omni/.venv/lib/python2.7/site-packages/django/template/base.py", line 233, in compile_nodelist
    return parser.parse()
  File "/data/fmc/pycharm_workspase/omni/.venv/lib/python2.7/site-packages/django/template/base.py", line 518, in parse
    raise self.error(token, e)
TemplateSyntaxError: default requires 2 arguments, 1 provided
WARNING  2016-10-08 00:11:16,091 django.request      [line 152 ] Not Found: /restapi/user/groups/
WARNING  2016-10-08 00:11:16,995 django.request      [line 152 ] Not Found: /restapi/user/groups/
WARNING  2016-10-08 00:44:28,307 django.request      [line 152 ] Not Found: /restapi/user/groups/
ERROR    2016-10-08 00:45:01,902 django.request      [line 124 ] Internal Server Error: /restapi/arch/products/
Traceback (most recent call last):
  File "/data/fmc/pycharm_workspase/omni/.venv/lib/python2.7/site-packages/django/core/handlers/exception.py", line 39, in inner
    response = get_response(request)
  File "/data/fmc/pycharm_workspase/omni/.venv/lib/python2.7/site-packages/django/core/handlers/base.py", line 249, in _legacy_get_response
    response = self._get_response(request)
  File "/data/fmc/pycharm_workspase/omni/.venv/lib/python2.7/site-packages/django/core/handlers/base.py", line 187, in _get_response
    response = self.process_exception_by_middleware(e, request)
  File "/data/fmc/pycharm_workspase/omni/.venv/lib/python2.7/site-packages/django/core/handlers/base.py", line 185, in _get_response
    response = wrapped_callback(request, *callback_args, **callback_kwargs)
  File "/data/fmc/pycharm_workspase/omni/.venv/lib/python2.7/site-packages/django/views/decorators/csrf.py", line 58, in wrapped_view
    return view_func(*args, **kwargs)
  File "/data/fmc/pycharm_workspase/omni/.venv/lib/python2.7/site-packages/django/views/generic/base.py", line 68, in view
    return self.dispatch(request, *args, **kwargs)
  File "/data/fmc/pycharm_workspase/omni/.venv/lib/python2.7/site-packages/rest_framework/views.py", line 474, in dispatch
    response = self.handle_exception(exc)
  File "/data/fmc/pycharm_workspase/omni/.venv/lib/python2.7/site-packages/rest_framework/views.py", line 434, in handle_exception
    self.raise_uncaught_exception(exc)
  File "/data/fmc/pycharm_workspase/omni/.venv/lib/python2.7/site-packages/rest_framework/views.py", line 471, in dispatch
    response = handler(request, *args, **kwargs)
  File "/data/fmc/pycharm_workspase/omni/.venv/lib/python2.7/site-packages/rest_framework/generics.py", line 240, in get
    return self.list(request, *args, **kwargs)
  File "/data/fmc/pycharm_workspase/omni/.venv/lib/python2.7/site-packages/rest_framework/mixins.py", line 48, in list
    return Response(serializer.data)
  File "/data/fmc/pycharm_workspase/omni/.venv/lib/python2.7/site-packages/rest_framework/serializers.py", line 701, in data
    ret = super(ListSerializer, self).data
  File "/data/fmc/pycharm_workspase/omni/.venv/lib/python2.7/site-packages/rest_framework/serializers.py", line 240, in data
    self._data = self.to_representation(self.instance)
  File "/data/fmc/pycharm_workspase/omni/.venv/lib/python2.7/site-packages/rest_framework/serializers.py", line 619, in to_representation
    self.child.to_representation(item) for item in iterable
  File "/data/fmc/pycharm_workspase/omni/.venv/lib/python2.7/site-packages/django/db/models/query.py", line 256, in __iter__
    self._fetch_all()
  File "/data/fmc/pycharm_workspase/omni/.venv/lib/python2.7/site-packages/django/db/models/query.py", line 1087, in _fetch_all
    self._result_cache = list(self.iterator())
  File "/data/fmc/pycharm_workspase/omni/.venv/lib/python2.7/site-packages/django/db/models/query.py", line 54, in __iter__
    results = compiler.execute_sql()
  File "/data/fmc/pycharm_workspase/omni/.venv/lib/python2.7/site-packages/django/db/models/sql/compiler.py", line 835, in execute_sql
    cursor.execute(sql, params)
  File "/data/fmc/pycharm_workspase/omni/.venv/lib/python2.7/site-packages/django/db/backends/utils.py", line 79, in execute
    return super(CursorDebugWrapper, self).execute(sql, params)
  File "/data/fmc/pycharm_workspase/omni/.venv/lib/python2.7/site-packages/django/db/backends/utils.py", line 64, in execute
    return self.cursor.execute(sql, params)
  File "/data/fmc/pycharm_workspase/omni/.venv/lib/python2.7/site-packages/django/db/utils.py", line 94, in __exit__
    six.reraise(dj_exc_type, dj_exc_value, traceback)
  File "/data/fmc/pycharm_workspase/omni/.venv/lib/python2.7/site-packages/django/db/backends/utils.py", line 64, in execute
    return self.cursor.execute(sql, params)
  File "/data/fmc/pycharm_workspase/omni/.venv/lib/python2.7/site-packages/django/db/backends/sqlite3/base.py", line 337, in execute
    return Database.Cursor.execute(self, query, params)
OperationalError: no such column: arch_product_info.ops_user_groups
ERROR    2016-10-08 00:54:07,498 django.request      [line 124 ] Internal Server Error: /restapi/arch/appids/update_all/
Traceback (most recent call last):
  File "/data/fmc/pycharm_workspase/omni/.venv/lib/python2.7/site-packages/django/core/handlers/exception.py", line 39, in inner
    response = get_response(request)
  File "/data/fmc/pycharm_workspase/omni/.venv/lib/python2.7/site-packages/django/core/handlers/base.py", line 249, in _legacy_get_response
    response = self._get_response(request)
  File "/data/fmc/pycharm_workspase/omni/.venv/lib/python2.7/site-packages/django/core/handlers/base.py", line 187, in _get_response
    response = self.process_exception_by_middleware(e, request)
  File "/data/fmc/pycharm_workspase/omni/.venv/lib/python2.7/site-packages/django/core/handlers/base.py", line 185, in _get_response
    response = wrapped_callback(request, *callback_args, **callback_kwargs)
  File "/data/fmc/pycharm_workspase/omni/.venv/lib/python2.7/site-packages/django/views/decorators/csrf.py", line 58, in wrapped_view
    return view_func(*args, **kwargs)
  File "/data/fmc/pycharm_workspase/omni/.venv/lib/python2.7/site-packages/django/views/generic/base.py", line 68, in view
    return self.dispatch(request, *args, **kwargs)
  File "/data/fmc/pycharm_workspase/omni/.venv/lib/python2.7/site-packages/rest_framework/views.py", line 474, in dispatch
    response = self.handle_exception(exc)
  File "/data/fmc/pycharm_workspase/omni/.venv/lib/python2.7/site-packages/rest_framework/views.py", line 434, in handle_exception
    self.raise_uncaught_exception(exc)
  File "/data/fmc/pycharm_workspase/omni/.venv/lib/python2.7/site-packages/rest_framework/views.py", line 471, in dispatch
    response = handler(request, *args, **kwargs)
  File "/data/fmc/pycharm_workspase/omni/omni/apps/arch/views/product.py", line 63, in post
    appid_info_list = self.get_appid_info_from_pms()
  File "/data/fmc/pycharm_workspase/omni/omni/apps/arch/views/product.py", line 45, in get_appid_info_from_pms
    response_obj = requests.get(get_appid_url)
  File "/data/fmc/pycharm_workspase/omni/.venv/lib/python2.7/site-packages/requests/api.py", line 70, in get
    return request('get', url, params=params, **kwargs)
  File "/data/fmc/pycharm_workspase/omni/.venv/lib/python2.7/site-packages/requests/api.py", line 56, in request
    return session.request(method=method, url=url, **kwargs)
  File "/data/fmc/pycharm_workspase/omni/.venv/lib/python2.7/site-packages/requests/sessions.py", line 475, in request
    resp = self.send(prep, **send_kwargs)
  File "/data/fmc/pycharm_workspase/omni/.venv/lib/python2.7/site-packages/requests/sessions.py", line 596, in send
    r = adapter.send(request, **kwargs)
  File "/data/fmc/pycharm_workspase/omni/.venv/lib/python2.7/site-packages/requests/adapters.py", line 487, in send
    raise ConnectionError(e, request=request)
ConnectionError: HTTPConnectionPool(host='pms.elenet.me', port=80): Max retries exceeded with url: /pmo.api/module/syncall (Caused by NewConnectionError('<requests.packages.urllib3.connection.HTTPConnection object at 0x103a31550>: Failed to establish a new connection: [Errno 60] Operation timed out',))
ERROR    2016-10-08 00:54:24,491 django.request      [line 124 ] Internal Server Error: /restapi/arch/appids/update_all/
Traceback (most recent call last):
  File "/data/fmc/pycharm_workspase/omni/.venv/lib/python2.7/site-packages/django/core/handlers/exception.py", line 39, in inner
    response = get_response(request)
  File "/data/fmc/pycharm_workspase/omni/.venv/lib/python2.7/site-packages/django/core/handlers/base.py", line 249, in _legacy_get_response
    response = self._get_response(request)
  File "/data/fmc/pycharm_workspase/omni/.venv/lib/python2.7/site-packages/django/core/handlers/base.py", line 187, in _get_response
    response = self.process_exception_by_middleware(e, request)
  File "/data/fmc/pycharm_workspase/omni/.venv/lib/python2.7/site-packages/django/core/handlers/base.py", line 185, in _get_response
    response = wrapped_callback(request, *callback_args, **callback_kwargs)
  File "/data/fmc/pycharm_workspase/omni/.venv/lib/python2.7/site-packages/django/views/decorators/csrf.py", line 58, in wrapped_view
    return view_func(*args, **kwargs)
  File "/data/fmc/pycharm_workspase/omni/.venv/lib/python2.7/site-packages/django/views/generic/base.py", line 68, in view
    return self.dispatch(request, *args, **kwargs)
  File "/data/fmc/pycharm_workspase/omni/.venv/lib/python2.7/site-packages/rest_framework/views.py", line 474, in dispatch
    response = self.handle_exception(exc)
  File "/data/fmc/pycharm_workspase/omni/.venv/lib/python2.7/site-packages/rest_framework/views.py", line 434, in handle_exception
    self.raise_uncaught_exception(exc)
  File "/data/fmc/pycharm_workspase/omni/.venv/lib/python2.7/site-packages/rest_framework/views.py", line 471, in dispatch
    response = handler(request, *args, **kwargs)
  File "/data/fmc/pycharm_workspase/omni/omni/apps/arch/views/product.py", line 63, in post
    appid_info_list = self.get_appid_info_from_pms()
  File "/data/fmc/pycharm_workspase/omni/omni/apps/arch/views/product.py", line 45, in get_appid_info_from_pms
    response_obj = requests.get(get_appid_url)
  File "/data/fmc/pycharm_workspase/omni/.venv/lib/python2.7/site-packages/requests/api.py", line 70, in get
    return request('get', url, params=params, **kwargs)
  File "/data/fmc/pycharm_workspase/omni/.venv/lib/python2.7/site-packages/requests/api.py", line 56, in request
    return session.request(method=method, url=url, **kwargs)
  File "/data/fmc/pycharm_workspase/omni/.venv/lib/python2.7/site-packages/requests/sessions.py", line 475, in request
    resp = self.send(prep, **send_kwargs)
  File "/data/fmc/pycharm_workspase/omni/.venv/lib/python2.7/site-packages/requests/sessions.py", line 596, in send
    r = adapter.send(request, **kwargs)
  File "/data/fmc/pycharm_workspase/omni/.venv/lib/python2.7/site-packages/requests/adapters.py", line 487, in send
    raise ConnectionError(e, request=request)
ConnectionError: HTTPConnectionPool(host='pms.elenet.me', port=80): Max retries exceeded with url: /pmo.api/module/syncall (Caused by NewConnectionError('<requests.packages.urllib3.connection.HTTPConnection object at 0x103a36350>: Failed to establish a new connection: [Errno 60] Operation timed out',))
ERROR    2016-10-08 00:54:37,124 django.request      [line 124 ] Internal Server Error: /restapi/arch/appids/update_all/
Traceback (most recent call last):
  File "/data/fmc/pycharm_workspase/omni/.venv/lib/python2.7/site-packages/django/core/handlers/exception.py", line 39, in inner
    response = get_response(request)
  File "/data/fmc/pycharm_workspase/omni/.venv/lib/python2.7/site-packages/django/core/handlers/base.py", line 249, in _legacy_get_response
    response = self._get_response(request)
  File "/data/fmc/pycharm_workspase/omni/.venv/lib/python2.7/site-packages/django/core/handlers/base.py", line 187, in _get_response
    response = self.process_exception_by_middleware(e, request)
  File "/data/fmc/pycharm_workspase/omni/.venv/lib/python2.7/site-packages/django/core/handlers/base.py", line 185, in _get_response
    response = wrapped_callback(request, *callback_args, **callback_kwargs)
  File "/data/fmc/pycharm_workspase/omni/.venv/lib/python2.7/site-packages/django/views/decorators/csrf.py", line 58, in wrapped_view
    return view_func(*args, **kwargs)
  File "/data/fmc/pycharm_workspase/omni/.venv/lib/python2.7/site-packages/django/views/generic/base.py", line 68, in view
    return self.dispatch(request, *args, **kwargs)
  File "/data/fmc/pycharm_workspase/omni/.venv/lib/python2.7/site-packages/rest_framework/views.py", line 474, in dispatch
    response = self.handle_exception(exc)
  File "/data/fmc/pycharm_workspase/omni/.venv/lib/python2.7/site-packages/rest_framework/views.py", line 434, in handle_exception
    self.raise_uncaught_exception(exc)
  File "/data/fmc/pycharm_workspase/omni/.venv/lib/python2.7/site-packages/rest_framework/views.py", line 471, in dispatch
    response = handler(request, *args, **kwargs)
  File "/data/fmc/pycharm_workspase/omni/omni/apps/arch/views/product.py", line 63, in post
    appid_info_list = self.get_appid_info_from_pms()
  File "/data/fmc/pycharm_workspase/omni/omni/apps/arch/views/product.py", line 45, in get_appid_info_from_pms
    response_obj = requests.get(get_appid_url)
  File "/data/fmc/pycharm_workspase/omni/.venv/lib/python2.7/site-packages/requests/api.py", line 70, in get
    return request('get', url, params=params, **kwargs)
  File "/data/fmc/pycharm_workspase/omni/.venv/lib/python2.7/site-packages/requests/api.py", line 56, in request
    return session.request(method=method, url=url, **kwargs)
  File "/data/fmc/pycharm_workspase/omni/.venv/lib/python2.7/site-packages/requests/sessions.py", line 475, in request
    resp = self.send(prep, **send_kwargs)
  File "/data/fmc/pycharm_workspase/omni/.venv/lib/python2.7/site-packages/requests/sessions.py", line 596, in send
    r = adapter.send(request, **kwargs)
  File "/data/fmc/pycharm_workspase/omni/.venv/lib/python2.7/site-packages/requests/adapters.py", line 487, in send
    raise ConnectionError(e, request=request)
ConnectionError: HTTPConnectionPool(host='pms.elenet.me', port=80): Max retries exceeded with url: /pmo.api/module/syncall (Caused by NewConnectionError('<requests.packages.urllib3.connection.HTTPConnection object at 0x103a3fc10>: Failed to establish a new connection: [Errno 60] Operation timed out',))
ERROR    2016-10-08 00:54:58,291 django.request      [line 124 ] Internal Server Error: /restapi/arch/appids/update_all/
Traceback (most recent call last):
  File "/data/fmc/pycharm_workspase/omni/.venv/lib/python2.7/site-packages/django/core/handlers/exception.py", line 39, in inner
    response = get_response(request)
  File "/data/fmc/pycharm_workspase/omni/.venv/lib/python2.7/site-packages/django/core/handlers/base.py", line 249, in _legacy_get_response
    response = self._get_response(request)
  File "/data/fmc/pycharm_workspase/omni/.venv/lib/python2.7/site-packages/django/core/handlers/base.py", line 187, in _get_response
    response = self.process_exception_by_middleware(e, request)
  File "/data/fmc/pycharm_workspase/omni/.venv/lib/python2.7/site-packages/django/core/handlers/base.py", line 185, in _get_response
    response = wrapped_callback(request, *callback_args, **callback_kwargs)
  File "/data/fmc/pycharm_workspase/omni/.venv/lib/python2.7/site-packages/django/views/decorators/csrf.py", line 58, in wrapped_view
    return view_func(*args, **kwargs)
  File "/data/fmc/pycharm_workspase/omni/.venv/lib/python2.7/site-packages/django/views/generic/base.py", line 68, in view
    return self.dispatch(request, *args, **kwargs)
  File "/data/fmc/pycharm_workspase/omni/.venv/lib/python2.7/site-packages/rest_framework/views.py", line 474, in dispatch
    response = self.handle_exception(exc)
  File "/data/fmc/pycharm_workspase/omni/.venv/lib/python2.7/site-packages/rest_framework/views.py", line 434, in handle_exception
    self.raise_uncaught_exception(exc)
  File "/data/fmc/pycharm_workspase/omni/.venv/lib/python2.7/site-packages/rest_framework/views.py", line 471, in dispatch
    response = handler(request, *args, **kwargs)
  File "/data/fmc/pycharm_workspase/omni/omni/apps/arch/views/product.py", line 63, in post
    appid_info_list = self.get_appid_info_from_pms()
  File "/data/fmc/pycharm_workspase/omni/omni/apps/arch/views/product.py", line 45, in get_appid_info_from_pms
    response_obj = requests.get(get_appid_url)
  File "/data/fmc/pycharm_workspase/omni/.venv/lib/python2.7/site-packages/requests/api.py", line 70, in get
    return request('get', url, params=params, **kwargs)
  File "/data/fmc/pycharm_workspase/omni/.venv/lib/python2.7/site-packages/requests/api.py", line 56, in request
    return session.request(method=method, url=url, **kwargs)
  File "/data/fmc/pycharm_workspase/omni/.venv/lib/python2.7/site-packages/requests/sessions.py", line 475, in request
    resp = self.send(prep, **send_kwargs)
  File "/data/fmc/pycharm_workspase/omni/.venv/lib/python2.7/site-packages/requests/sessions.py", line 596, in send
    r = adapter.send(request, **kwargs)
  File "/data/fmc/pycharm_workspase/omni/.venv/lib/python2.7/site-packages/requests/adapters.py", line 487, in send
    raise ConnectionError(e, request=request)
ConnectionError: HTTPConnectionPool(host='pms.elenet.me', port=80): Max retries exceeded with url: /pmo.api/module/syncall (Caused by NewConnectionError('<requests.packages.urllib3.connection.HTTPConnection object at 0x103a4abd0>: Failed to establish a new connection: [Errno 60] Operation timed out',))
WARNING  2016-10-08 00:56:12,591 django.request      [line 152 ] Not Found: /restapi/user/groups/
WARNING  2016-10-08 01:00:45,846 django.request      [line 152 ] Not Found: /restapi/user/groups/
WARNING  2016-10-08 01:04:55,049 django.request      [line 152 ] Not Found: /restapi/user/groups/
WARNING  2016-10-08 01:04:55,759 django.request      [line 152 ] Not Found: /restapi/user/groups/
WARNING  2016-10-08 02:30:05,544 django.request      [line 152 ] Not Found: //restapi/arch/appids/
WARNING  2016-10-08 02:30:16,235 django.request      [line 152 ] Not Found: //restapi/arch/appids/
WARNING  2016-10-08 02:30:45,905 django.request      [line 152 ] Not Found: /restapi//arch/appids/
WARNING  2016-10-08 02:57:05,451 django.request      [line 152 ] Not Found: /cmc/department/1/
WARNING  2016-10-08 03:05:10,105 django.request      [line 152 ] Not Found: /arch/appid/11/
WARNING  2016-10-08 03:05:15,068 django.request      [line 152 ] Not Found: /arch/appid/1/
WARNING  2016-10-08 03:51:04,462 django.request      [line 152 ] Not Found: /arch/appid/1/update/
WARNING  2016-10-08 03:51:10,536 django.request      [line 152 ] Not Found: /arch/appid/7/update/
WARNING  2016-10-08 03:52:25,345 django.request      [line 152 ] Not Found: /arch/appid/1/update/
WARNING  2016-10-08 10:48:52,942 django.request      [line 152 ] Not Found: /arch/appid/1/update/
WARNING  2016-10-08 11:22:22,941 django.request      [line 152 ] Not Found: /arch/appid/1/update/
ERROR    2016-10-08 11:23:12,183 django.request      [line 124 ] Internal Server Error: /arch/appid/1/update/
Traceback (most recent call last):
  File "/data/fmc/pycharm_workspase/omni/.venv/lib/python2.7/site-packages/django/core/handlers/exception.py", line 39, in inner
    response = get_response(request)
  File "/data/fmc/pycharm_workspase/omni/.venv/lib/python2.7/site-packages/django/core/handlers/base.py", line 249, in _legacy_get_response
    response = self._get_response(request)
  File "/data/fmc/pycharm_workspase/omni/.venv/lib/python2.7/site-packages/django/core/handlers/base.py", line 187, in _get_response
    response = self.process_exception_by_middleware(e, request)
  File "/data/fmc/pycharm_workspase/omni/.venv/lib/python2.7/site-packages/django/core/handlers/base.py", line 185, in _get_response
    response = wrapped_callback(request, *callback_args, **callback_kwargs)
  File "/data/fmc/pycharm_workspase/omni/.venv/lib/python2.7/site-packages/django/views/generic/base.py", line 68, in view
    return self.dispatch(request, *args, **kwargs)
  File "/data/fmc/pycharm_workspase/omni/.venv/lib/python2.7/site-packages/django/views/generic/base.py", line 88, in dispatch
    return handler(request, *args, **kwargs)
  File "/data/fmc/pycharm_workspase/omni/.venv/lib/python2.7/site-packages/django/views/generic/edit.py", line 235, in get
    self.object = self.get_object()
  File "/data/fmc/pycharm_workspase/omni/.venv/lib/python2.7/site-packages/django/views/generic/detail.py", line 32, in get_object
    queryset = self.get_queryset()
  File "/data/fmc/pycharm_workspase/omni/.venv/lib/python2.7/site-packages/django/views/generic/detail.py", line 74, in get_queryset
    'cls': self.__class__.__name__
ImproperlyConfigured: AppIdUpdateTemplateView is missing a QuerySet. Define AppIdUpdateTemplateView.model, AppIdUpdateTemplateView.queryset, or override AppIdUpdateTemplateView.get_queryset().
ERROR    2016-10-08 11:28:20,605 django.request      [line 124 ] Internal Server Error: ///restapi//arch/appids/
Traceback (most recent call last):
  File "/data/fmc/pycharm_workspase/omni/.venv/lib/python2.7/site-packages/django/core/handlers/exception.py", line 39, in inner
    response = get_response(request)
  File "/data/fmc/pycharm_workspase/omni/.venv/lib/python2.7/site-packages/django/core/handlers/base.py", line 249, in _legacy_get_response
    response = self._get_response(request)
  File "/data/fmc/pycharm_workspase/omni/.venv/lib/python2.7/site-packages/django/core/handlers/base.py", line 187, in _get_response
    response = self.process_exception_by_middleware(e, request)
  File "/data/fmc/pycharm_workspase/omni/.venv/lib/python2.7/site-packages/django/core/handlers/base.py", line 185, in _get_response
    response = wrapped_callback(request, *callback_args, **callback_kwargs)
  File "/data/fmc/pycharm_workspase/omni/.venv/lib/python2.7/site-packages/django/views/decorators/csrf.py", line 58, in wrapped_view
    return view_func(*args, **kwargs)
  File "/data/fmc/pycharm_workspase/omni/.venv/lib/python2.7/site-packages/django/views/generic/base.py", line 68, in view
    return self.dispatch(request, *args, **kwargs)
  File "/data/fmc/pycharm_workspase/omni/.venv/lib/python2.7/site-packages/rest_framework/views.py", line 474, in dispatch
    response = self.handle_exception(exc)
  File "/data/fmc/pycharm_workspase/omni/.venv/lib/python2.7/site-packages/rest_framework/views.py", line 434, in handle_exception
    self.raise_uncaught_exception(exc)
  File "/data/fmc/pycharm_workspase/omni/.venv/lib/python2.7/site-packages/rest_framework/views.py", line 471, in dispatch
    response = handler(request, *args, **kwargs)
  File "/data/fmc/pycharm_workspase/omni/.venv/lib/python2.7/site-packages/rest_framework/generics.py", line 200, in get
    return self.list(request, *args, **kwargs)
  File "/data/fmc/pycharm_workspase/omni/omni/libs/django/view/mixin.py", line 85, in list
    response_data = self.get_response_data(request, serializer)
  File "/data/fmc/pycharm_workspase/omni/omni/libs/django/view/mixin.py", line 95, in get_response_data
    response_data = self.clean_relation_fields(request, serializer.data)
  File "/data/fmc/pycharm_workspase/omni/omni/libs/django/view/mixin.py", line 62, in clean_relation_fields
    for obj_data in response_data if obj_data[relation_field_name]]
KeyError: u'department_id'
WARNING  2016-10-08 11:53:49,776 django.request      [line 152 ] Not Found: /restapi/user/groups/
WARNING  2016-10-08 11:53:50,616 django.request      [line 152 ] Not Found: /restapi/user/groups/
WARNING  2016-10-08 15:17:26,178 django.request      [line 152 ] Not Found: /restapi/user/groups/
ERROR    2016-10-08 23:13:00,764 django.request      [line 124 ] Internal Server Error: /restapi/arch/appids/18
Traceback (most recent call last):
  File "/data/fmc/pycharm_workspase/omni/.venv/lib/python2.7/site-packages/django/core/handlers/exception.py", line 39, in inner
    response = get_response(request)
  File "/data/fmc/pycharm_workspase/omni/.venv/lib/python2.7/site-packages/django/core/handlers/base.py", line 244, in _legacy_get_response
    response = middleware_method(request)
  File "/data/fmc/pycharm_workspase/omni/.venv/lib/python2.7/site-packages/django/middleware/common.py", line 63, in process_request
    path = self.get_full_path_with_slash(request)
  File "/data/fmc/pycharm_workspase/omni/.venv/lib/python2.7/site-packages/django/middleware/common.py", line 101, in get_full_path_with_slash
    'url': request.get_host() + new_path,
RuntimeError: You called this URL via POST, but the URL doesn't end in a slash and you have APPEND_SLASH set. Django can't redirect to the slash URL while maintaining POST data. Change your form to point to 127.0.0.1:8000/restapi/arch/appids/18/ (note the trailing slash), or set APPEND_SLASH=False in your Django settings.
ERROR    2016-10-09 18:53:38,247 django.request      [line 124 ] Internal Server Error: /restapi/arch/appids/update_all/
Traceback (most recent call last):
  File "/data/fmc/pycharm_workspase/omni/.venv/lib/python2.7/site-packages/django/core/handlers/exception.py", line 39, in inner
    response = get_response(request)
  File "/data/fmc/pycharm_workspase/omni/.venv/lib/python2.7/site-packages/django/core/handlers/base.py", line 249, in _legacy_get_response
    response = self._get_response(request)
  File "/data/fmc/pycharm_workspase/omni/.venv/lib/python2.7/site-packages/django/core/handlers/base.py", line 187, in _get_response
    response = self.process_exception_by_middleware(e, request)
  File "/data/fmc/pycharm_workspase/omni/.venv/lib/python2.7/site-packages/django/core/handlers/base.py", line 185, in _get_response
    response = wrapped_callback(request, *callback_args, **callback_kwargs)
  File "/data/fmc/pycharm_workspase/omni/.venv/lib/python2.7/site-packages/django/views/decorators/csrf.py", line 58, in wrapped_view
    return view_func(*args, **kwargs)
  File "/data/fmc/pycharm_workspase/omni/.venv/lib/python2.7/site-packages/django/views/generic/base.py", line 68, in view
    return self.dispatch(request, *args, **kwargs)
  File "/data/fmc/pycharm_workspase/omni/.venv/lib/python2.7/site-packages/rest_framework/views.py", line 474, in dispatch
    response = self.handle_exception(exc)
  File "/data/fmc/pycharm_workspase/omni/.venv/lib/python2.7/site-packages/rest_framework/views.py", line 434, in handle_exception
    self.raise_uncaught_exception(exc)
  File "/data/fmc/pycharm_workspase/omni/.venv/lib/python2.7/site-packages/rest_framework/views.py", line 471, in dispatch
    response = handler(request, *args, **kwargs)
  File "/data/fmc/pycharm_workspase/omni/omni/apps/arch/views/product.py", line 79, in post
    appid_info_obj, created = AppIdModel.objects.update_or_create(**appid_obj_data)
  File "/data/fmc/pycharm_workspase/omni/.venv/lib/python2.7/site-packages/django/db/models/manager.py", line 85, in manager_method
    return getattr(self.get_queryset(), name)(*args, **kwargs)
  File "/data/fmc/pycharm_workspase/omni/.venv/lib/python2.7/site-packages/django/db/models/query.py", line 488, in update_or_create
    obj = self.get(**lookup)
  File "/data/fmc/pycharm_workspase/omni/.venv/lib/python2.7/site-packages/django/db/models/query.py", line 376, in get
    clone = self.filter(*args, **kwargs)
  File "/data/fmc/pycharm_workspase/omni/.venv/lib/python2.7/site-packages/django/db/models/query.py", line 796, in filter
    return self._filter_or_exclude(False, *args, **kwargs)
  File "/data/fmc/pycharm_workspase/omni/.venv/lib/python2.7/site-packages/django/db/models/query.py", line 814, in _filter_or_exclude
    clone.query.add_q(Q(*args, **kwargs))
  File "/data/fmc/pycharm_workspase/omni/.venv/lib/python2.7/site-packages/django/db/models/sql/query.py", line 1227, in add_q
    clause, _ = self._add_q(q_object, self.used_aliases)
  File "/data/fmc/pycharm_workspase/omni/.venv/lib/python2.7/site-packages/django/db/models/sql/query.py", line 1253, in _add_q
    allow_joins=allow_joins, split_subq=split_subq,
  File "/data/fmc/pycharm_workspase/omni/.venv/lib/python2.7/site-packages/django/db/models/sql/query.py", line 1133, in build_filter
    lookups, parts, reffed_expression = self.solve_lookup_type(arg)
  File "/data/fmc/pycharm_workspase/omni/.venv/lib/python2.7/site-packages/django/db/models/sql/query.py", line 1019, in solve_lookup_type
    _, field, _, lookup_parts = self.names_to_path(lookup_splitted, self.get_meta())
  File "/data/fmc/pycharm_workspase/omni/.venv/lib/python2.7/site-packages/django/db/models/sql/query.py", line 1327, in names_to_path
    "Choices are: %s" % (name, ", ".join(available)))
FieldError: Cannot resolve keyword 'department_id' into field. Choices are: app_arch, appidrelateclustertmplmodel, clustertmplversionmodel, create_time, dev_department, dev_department_id, dev_user_group, http_port, id, life_cycle, monitor_port, name, ops_user_group, owner, owner_id, product, product_id, project, project_id, thrift_port, udp_port, update_time, visible_name
WARNING  2016-10-09 19:05:17,551 django.request      [line 152 ] Not Found: /restapi/user/groups/
WARNING  2016-10-09 19:05:19,437 django.request      [line 152 ] Not Found: /restapi/user/groups/
WARNING  2016-10-09 19:34:16,182 django.request      [line 152 ] Not Found: /restapi/user/groups/
WARNING  2016-10-09 20:03:44,110 django.request      [line 152 ] Not Found: /restapi/user/groups/
WARNING  2016-10-09 20:04:23,345 django.request      [line 152 ] Not Found: /restapi/user/groups/
WARNING  2016-10-09 20:05:52,513 django.request      [line 152 ] Not Found: /arch/appid/undefined/update/
ERROR    2016-10-09 20:07:29,796 django.request      [line 124 ] Internal Server Error: /restapi/arch/appids/
Traceback (most recent call last):
  File "/data/fmc/pycharm_workspase/omni/.venv/lib/python2.7/site-packages/django/core/handlers/exception.py", line 39, in inner
    response = get_response(request)
  File "/data/fmc/pycharm_workspase/omni/.venv/lib/python2.7/site-packages/django/core/handlers/base.py", line 249, in _legacy_get_response
    response = self._get_response(request)
  File "/data/fmc/pycharm_workspase/omni/.venv/lib/python2.7/site-packages/django/core/handlers/base.py", line 187, in _get_response
    response = self.process_exception_by_middleware(e, request)
  File "/data/fmc/pycharm_workspase/omni/.venv/lib/python2.7/site-packages/django/core/handlers/base.py", line 185, in _get_response
    response = wrapped_callback(request, *callback_args, **callback_kwargs)
  File "/data/fmc/pycharm_workspase/omni/.venv/lib/python2.7/site-packages/django/views/decorators/csrf.py", line 58, in wrapped_view
    return view_func(*args, **kwargs)
  File "/data/fmc/pycharm_workspase/omni/.venv/lib/python2.7/site-packages/django/views/generic/base.py", line 68, in view
    return self.dispatch(request, *args, **kwargs)
  File "/data/fmc/pycharm_workspase/omni/.venv/lib/python2.7/site-packages/rest_framework/views.py", line 474, in dispatch
    response = self.handle_exception(exc)
  File "/data/fmc/pycharm_workspase/omni/.venv/lib/python2.7/site-packages/rest_framework/views.py", line 434, in handle_exception
    self.raise_uncaught_exception(exc)
  File "/data/fmc/pycharm_workspase/omni/.venv/lib/python2.7/site-packages/rest_framework/views.py", line 471, in dispatch
    response = handler(request, *args, **kwargs)
  File "/data/fmc/pycharm_workspase/omni/.venv/lib/python2.7/site-packages/rest_framework/generics.py", line 200, in get
    return self.list(request, *args, **kwargs)
  File "/data/fmc/pycharm_workspase/omni/omni/libs/django/view/mixin.py", line 82, in list
    response_data = self.get_response_data(request, serializer)
  File "/data/fmc/pycharm_workspase/omni/omni/libs/django/view/mixin.py", line 92, in get_response_data
    response_data = self.clean_relation_fields(request, serializer.data)
  File "/data/fmc/pycharm_workspase/omni/.venv/lib/python2.7/site-packages/rest_framework/serializers.py", line 701, in data
    ret = super(ListSerializer, self).data
  File "/data/fmc/pycharm_workspase/omni/.venv/lib/python2.7/site-packages/rest_framework/serializers.py", line 240, in data
    self._data = self.to_representation(self.instance)
  File "/data/fmc/pycharm_workspase/omni/.venv/lib/python2.7/site-packages/rest_framework/serializers.py", line 619, in to_representation
    self.child.to_representation(item) for item in iterable
  File "/data/fmc/pycharm_workspase/omni/.venv/lib/python2.7/site-packages/rest_framework/serializers.py", line 464, in to_representation
    attribute = field.get_attribute(instance)
  File "/data/fmc/pycharm_workspase/omni/.venv/lib/python2.7/site-packages/rest_framework/relations.py", line 491, in get_attribute
    relationship = get_attribute(instance, self.source_attrs)
  File "/data/fmc/pycharm_workspase/omni/.venv/lib/python2.7/site-packages/rest_framework/fields.py", line 83, in get_attribute
    instance = getattr(instance, attr)
  File "/data/fmc/pycharm_workspase/omni/.venv/lib/python2.7/site-packages/django/db/models/fields/related_descriptors.py", line 476, in __get__
    return self.related_manager_cls(instance)
  File "/data/fmc/pycharm_workspase/omni/.venv/lib/python2.7/site-packages/django/db/models/fields/related_descriptors.py", line 771, in __init__
    self.source_field = self.through._meta.get_field(self.source_field_name)
  File "/data/fmc/pycharm_workspase/omni/.venv/lib/python2.7/site-packages/django/db/models/options.py", line 619, in get_field
    raise FieldDoesNotExist('%s has no field named %r' % (self.object_name, field_name))
FieldDoesNotExist: UserGroupRelateAppIdModel has no field named None
ERROR    2016-10-09 20:08:34,102 django.request      [line 124 ] Internal Server Error: /restapi/arch/appids/
Traceback (most recent call last):
  File "/data/fmc/pycharm_workspase/omni/.venv/lib/python2.7/site-packages/django/core/handlers/exception.py", line 39, in inner
    response = get_response(request)
  File "/data/fmc/pycharm_workspase/omni/.venv/lib/python2.7/site-packages/django/core/handlers/base.py", line 249, in _legacy_get_response
    response = self._get_response(request)
  File "/data/fmc/pycharm_workspase/omni/.venv/lib/python2.7/site-packages/django/core/handlers/base.py", line 187, in _get_response
    response = self.process_exception_by_middleware(e, request)
  File "/data/fmc/pycharm_workspase/omni/.venv/lib/python2.7/site-packages/django/core/handlers/base.py", line 185, in _get_response
    response = wrapped_callback(request, *callback_args, **callback_kwargs)
  File "/data/fmc/pycharm_workspase/omni/.venv/lib/python2.7/site-packages/django/views/decorators/csrf.py", line 58, in wrapped_view
    return view_func(*args, **kwargs)
  File "/data/fmc/pycharm_workspase/omni/.venv/lib/python2.7/site-packages/django/views/generic/base.py", line 68, in view
    return self.dispatch(request, *args, **kwargs)
  File "/data/fmc/pycharm_workspase/omni/.venv/lib/python2.7/site-packages/rest_framework/views.py", line 474, in dispatch
    response = self.handle_exception(exc)
  File "/data/fmc/pycharm_workspase/omni/.venv/lib/python2.7/site-packages/rest_framework/views.py", line 434, in handle_exception
    self.raise_uncaught_exception(exc)
  File "/data/fmc/pycharm_workspase/omni/.venv/lib/python2.7/site-packages/rest_framework/views.py", line 471, in dispatch
    response = handler(request, *args, **kwargs)
  File "/data/fmc/pycharm_workspase/omni/.venv/lib/python2.7/site-packages/rest_framework/generics.py", line 200, in get
    return self.list(request, *args, **kwargs)
  File "/data/fmc/pycharm_workspase/omni/omni/libs/django/view/mixin.py", line 82, in list
    response_data = self.get_response_data(request, serializer)
  File "/data/fmc/pycharm_workspase/omni/omni/libs/django/view/mixin.py", line 92, in get_response_data
    response_data = self.clean_relation_fields(request, serializer.data)
  File "/data/fmc/pycharm_workspase/omni/.venv/lib/python2.7/site-packages/rest_framework/serializers.py", line 701, in data
    ret = super(ListSerializer, self).data
  File "/data/fmc/pycharm_workspase/omni/.venv/lib/python2.7/site-packages/rest_framework/serializers.py", line 240, in data
    self._data = self.to_representation(self.instance)
  File "/data/fmc/pycharm_workspase/omni/.venv/lib/python2.7/site-packages/rest_framework/serializers.py", line 619, in to_representation
    self.child.to_representation(item) for item in iterable
  File "/data/fmc/pycharm_workspase/omni/.venv/lib/python2.7/site-packages/rest_framework/serializers.py", line 464, in to_representation
    attribute = field.get_attribute(instance)
  File "/data/fmc/pycharm_workspase/omni/.venv/lib/python2.7/site-packages/rest_framework/relations.py", line 491, in get_attribute
    relationship = get_attribute(instance, self.source_attrs)
  File "/data/fmc/pycharm_workspase/omni/.venv/lib/python2.7/site-packages/rest_framework/fields.py", line 83, in get_attribute
    instance = getattr(instance, attr)
  File "/data/fmc/pycharm_workspase/omni/.venv/lib/python2.7/site-packages/django/db/models/fields/related_descriptors.py", line 476, in __get__
    return self.related_manager_cls(instance)
  File "/data/fmc/pycharm_workspase/omni/.venv/lib/python2.7/site-packages/django/db/models/fields/related_descriptors.py", line 771, in __init__
    self.source_field = self.through._meta.get_field(self.source_field_name)
  File "/data/fmc/pycharm_workspase/omni/.venv/lib/python2.7/site-packages/django/db/models/options.py", line 619, in get_field
    raise FieldDoesNotExist('%s has no field named %r' % (self.object_name, field_name))
FieldDoesNotExist: UserGroupRelateAppIdModel has no field named None
ERROR    2016-10-09 20:08:35,505 django.request      [line 124 ] Internal Server Error: /restapi/arch/appids/
Traceback (most recent call last):
  File "/data/fmc/pycharm_workspase/omni/.venv/lib/python2.7/site-packages/django/core/handlers/exception.py", line 39, in inner
    response = get_response(request)
  File "/data/fmc/pycharm_workspase/omni/.venv/lib/python2.7/site-packages/django/core/handlers/base.py", line 249, in _legacy_get_response
    response = self._get_response(request)
  File "/data/fmc/pycharm_workspase/omni/.venv/lib/python2.7/site-packages/django/core/handlers/base.py", line 187, in _get_response
    response = self.process_exception_by_middleware(e, request)
  File "/data/fmc/pycharm_workspase/omni/.venv/lib/python2.7/site-packages/django/core/handlers/base.py", line 185, in _get_response
    response = wrapped_callback(request, *callback_args, **callback_kwargs)
  File "/data/fmc/pycharm_workspase/omni/.venv/lib/python2.7/site-packages/django/views/decorators/csrf.py", line 58, in wrapped_view
    return view_func(*args, **kwargs)
  File "/data/fmc/pycharm_workspase/omni/.venv/lib/python2.7/site-packages/django/views/generic/base.py", line 68, in view
    return self.dispatch(request, *args, **kwargs)
  File "/data/fmc/pycharm_workspase/omni/.venv/lib/python2.7/site-packages/rest_framework/views.py", line 474, in dispatch
    response = self.handle_exception(exc)
  File "/data/fmc/pycharm_workspase/omni/.venv/lib/python2.7/site-packages/rest_framework/views.py", line 434, in handle_exception
    self.raise_uncaught_exception(exc)
  File "/data/fmc/pycharm_workspase/omni/.venv/lib/python2.7/site-packages/rest_framework/views.py", line 471, in dispatch
    response = handler(request, *args, **kwargs)
  File "/data/fmc/pycharm_workspase/omni/.venv/lib/python2.7/site-packages/rest_framework/generics.py", line 200, in get
    return self.list(request, *args, **kwargs)
  File "/data/fmc/pycharm_workspase/omni/omni/libs/django/view/mixin.py", line 82, in list
    response_data = self.get_response_data(request, serializer)
  File "/data/fmc/pycharm_workspase/omni/omni/libs/django/view/mixin.py", line 92, in get_response_data
    response_data = self.clean_relation_fields(request, serializer.data)
  File "/data/fmc/pycharm_workspase/omni/.venv/lib/python2.7/site-packages/rest_framework/serializers.py", line 701, in data
    ret = super(ListSerializer, self).data
  File "/data/fmc/pycharm_workspase/omni/.venv/lib/python2.7/site-packages/rest_framework/serializers.py", line 240, in data
    self._data = self.to_representation(self.instance)
  File "/data/fmc/pycharm_workspase/omni/.venv/lib/python2.7/site-packages/rest_framework/serializers.py", line 619, in to_representation
    self.child.to_representation(item) for item in iterable
  File "/data/fmc/pycharm_workspase/omni/.venv/lib/python2.7/site-packages/rest_framework/serializers.py", line 464, in to_representation
    attribute = field.get_attribute(instance)
  File "/data/fmc/pycharm_workspase/omni/.venv/lib/python2.7/site-packages/rest_framework/relations.py", line 491, in get_attribute
    relationship = get_attribute(instance, self.source_attrs)
  File "/data/fmc/pycharm_workspase/omni/.venv/lib/python2.7/site-packages/rest_framework/fields.py", line 83, in get_attribute
    instance = getattr(instance, attr)
  File "/data/fmc/pycharm_workspase/omni/.venv/lib/python2.7/site-packages/django/db/models/fields/related_descriptors.py", line 476, in __get__
    return self.related_manager_cls(instance)
  File "/data/fmc/pycharm_workspase/omni/.venv/lib/python2.7/site-packages/django/db/models/fields/related_descriptors.py", line 771, in __init__
    self.source_field = self.through._meta.get_field(self.source_field_name)
  File "/data/fmc/pycharm_workspase/omni/.venv/lib/python2.7/site-packages/django/db/models/options.py", line 619, in get_field
    raise FieldDoesNotExist('%s has no field named %r' % (self.object_name, field_name))
FieldDoesNotExist: UserGroupRelateAppIdModel has no field named None
ERROR    2016-10-09 20:08:36,294 django.request      [line 124 ] Internal Server Error: /restapi/arch/appids/
Traceback (most recent call last):
  File "/data/fmc/pycharm_workspase/omni/.venv/lib/python2.7/site-packages/django/core/handlers/exception.py", line 39, in inner
    response = get_response(request)
  File "/data/fmc/pycharm_workspase/omni/.venv/lib/python2.7/site-packages/django/core/handlers/base.py", line 249, in _legacy_get_response
    response = self._get_response(request)
  File "/data/fmc/pycharm_workspase/omni/.venv/lib/python2.7/site-packages/django/core/handlers/base.py", line 187, in _get_response
    response = self.process_exception_by_middleware(e, request)
  File "/data/fmc/pycharm_workspase/omni/.venv/lib/python2.7/site-packages/django/core/handlers/base.py", line 185, in _get_response
    response = wrapped_callback(request, *callback_args, **callback_kwargs)
  File "/data/fmc/pycharm_workspase/omni/.venv/lib/python2.7/site-packages/django/views/decorators/csrf.py", line 58, in wrapped_view
    return view_func(*args, **kwargs)
  File "/data/fmc/pycharm_workspase/omni/.venv/lib/python2.7/site-packages/django/views/generic/base.py", line 68, in view
    return self.dispatch(request, *args, **kwargs)
  File "/data/fmc/pycharm_workspase/omni/.venv/lib/python2.7/site-packages/rest_framework/views.py", line 474, in dispatch
    response = self.handle_exception(exc)
  File "/data/fmc/pycharm_workspase/omni/.venv/lib/python2.7/site-packages/rest_framework/views.py", line 434, in handle_exception
    self.raise_uncaught_exception(exc)
  File "/data/fmc/pycharm_workspase/omni/.venv/lib/python2.7/site-packages/rest_framework/views.py", line 471, in dispatch
    response = handler(request, *args, **kwargs)
  File "/data/fmc/pycharm_workspase/omni/.venv/lib/python2.7/site-packages/rest_framework/generics.py", line 200, in get
    return self.list(request, *args, **kwargs)
  File "/data/fmc/pycharm_workspase/omni/omni/libs/django/view/mixin.py", line 82, in list
    response_data = self.get_response_data(request, serializer)
  File "/data/fmc/pycharm_workspase/omni/omni/libs/django/view/mixin.py", line 92, in get_response_data
    response_data = self.clean_relation_fields(request, serializer.data)
  File "/data/fmc/pycharm_workspase/omni/.venv/lib/python2.7/site-packages/rest_framework/serializers.py", line 701, in data
    ret = super(ListSerializer, self).data
  File "/data/fmc/pycharm_workspase/omni/.venv/lib/python2.7/site-packages/rest_framework/serializers.py", line 240, in data
    self._data = self.to_representation(self.instance)
  File "/data/fmc/pycharm_workspase/omni/.venv/lib/python2.7/site-packages/rest_framework/serializers.py", line 619, in to_representation
    self.child.to_representation(item) for item in iterable
  File "/data/fmc/pycharm_workspase/omni/.venv/lib/python2.7/site-packages/rest_framework/serializers.py", line 464, in to_representation
    attribute = field.get_attribute(instance)
  File "/data/fmc/pycharm_workspase/omni/.venv/lib/python2.7/site-packages/rest_framework/relations.py", line 491, in get_attribute
    relationship = get_attribute(instance, self.source_attrs)
  File "/data/fmc/pycharm_workspase/omni/.venv/lib/python2.7/site-packages/rest_framework/fields.py", line 83, in get_attribute
    instance = getattr(instance, attr)
  File "/data/fmc/pycharm_workspase/omni/.venv/lib/python2.7/site-packages/django/db/models/fields/related_descriptors.py", line 476, in __get__
    return self.related_manager_cls(instance)
  File "/data/fmc/pycharm_workspase/omni/.venv/lib/python2.7/site-packages/django/db/models/fields/related_descriptors.py", line 771, in __init__
    self.source_field = self.through._meta.get_field(self.source_field_name)
  File "/data/fmc/pycharm_workspase/omni/.venv/lib/python2.7/site-packages/django/db/models/options.py", line 619, in get_field
    raise FieldDoesNotExist('%s has no field named %r' % (self.object_name, field_name))
FieldDoesNotExist: UserGroupRelateAppIdModel has no field named None
ERROR    2016-10-09 20:08:37,249 django.request      [line 124 ] Internal Server Error: /restapi/arch/appids/
Traceback (most recent call last):
  File "/data/fmc/pycharm_workspase/omni/.venv/lib/python2.7/site-packages/django/core/handlers/exception.py", line 39, in inner
    response = get_response(request)
  File "/data/fmc/pycharm_workspase/omni/.venv/lib/python2.7/site-packages/django/core/handlers/base.py", line 249, in _legacy_get_response
    response = self._get_response(request)
  File "/data/fmc/pycharm_workspase/omni/.venv/lib/python2.7/site-packages/django/core/handlers/base.py", line 187, in _get_response
    response = self.process_exception_by_middleware(e, request)
  File "/data/fmc/pycharm_workspase/omni/.venv/lib/python2.7/site-packages/django/core/handlers/base.py", line 185, in _get_response
    response = wrapped_callback(request, *callback_args, **callback_kwargs)
  File "/data/fmc/pycharm_workspase/omni/.venv/lib/python2.7/site-packages/django/views/decorators/csrf.py", line 58, in wrapped_view
    return view_func(*args, **kwargs)
  File "/data/fmc/pycharm_workspase/omni/.venv/lib/python2.7/site-packages/django/views/generic/base.py", line 68, in view
    return self.dispatch(request, *args, **kwargs)
  File "/data/fmc/pycharm_workspase/omni/.venv/lib/python2.7/site-packages/rest_framework/views.py", line 474, in dispatch
    response = self.handle_exception(exc)
  File "/data/fmc/pycharm_workspase/omni/.venv/lib/python2.7/site-packages/rest_framework/views.py", line 434, in handle_exception
    self.raise_uncaught_exception(exc)
  File "/data/fmc/pycharm_workspase/omni/.venv/lib/python2.7/site-packages/rest_framework/views.py", line 471, in dispatch
    response = handler(request, *args, **kwargs)
  File "/data/fmc/pycharm_workspase/omni/.venv/lib/python2.7/site-packages/rest_framework/generics.py", line 200, in get
    return self.list(request, *args, **kwargs)
  File "/data/fmc/pycharm_workspase/omni/omni/libs/django/view/mixin.py", line 82, in list
    response_data = self.get_response_data(request, serializer)
  File "/data/fmc/pycharm_workspase/omni/omni/libs/django/view/mixin.py", line 92, in get_response_data
    response_data = self.clean_relation_fields(request, serializer.data)
  File "/data/fmc/pycharm_workspase/omni/.venv/lib/python2.7/site-packages/rest_framework/serializers.py", line 701, in data
    ret = super(ListSerializer, self).data
  File "/data/fmc/pycharm_workspase/omni/.venv/lib/python2.7/site-packages/rest_framework/serializers.py", line 240, in data
    self._data = self.to_representation(self.instance)
  File "/data/fmc/pycharm_workspase/omni/.venv/lib/python2.7/site-packages/rest_framework/serializers.py", line 619, in to_representation
    self.child.to_representation(item) for item in iterable
  File "/data/fmc/pycharm_workspase/omni/.venv/lib/python2.7/site-packages/rest_framework/serializers.py", line 464, in to_representation
    attribute = field.get_attribute(instance)
  File "/data/fmc/pycharm_workspase/omni/.venv/lib/python2.7/site-packages/rest_framework/relations.py", line 491, in get_attribute
    relationship = get_attribute(instance, self.source_attrs)
  File "/data/fmc/pycharm_workspase/omni/.venv/lib/python2.7/site-packages/rest_framework/fields.py", line 83, in get_attribute
    instance = getattr(instance, attr)
  File "/data/fmc/pycharm_workspase/omni/.venv/lib/python2.7/site-packages/django/db/models/fields/related_descriptors.py", line 476, in __get__
    return self.related_manager_cls(instance)
  File "/data/fmc/pycharm_workspase/omni/.venv/lib/python2.7/site-packages/django/db/models/fields/related_descriptors.py", line 771, in __init__
    self.source_field = self.through._meta.get_field(self.source_field_name)
  File "/data/fmc/pycharm_workspase/omni/.venv/lib/python2.7/site-packages/django/db/models/options.py", line 619, in get_field
    raise FieldDoesNotExist('%s has no field named %r' % (self.object_name, field_name))
FieldDoesNotExist: UserGroupRelateAppIdModel has no field named None
ERROR    2016-10-09 20:10:25,857 django.request      [line 124 ] Internal Server Error: /restapi/arch/appids/
Traceback (most recent call last):
  File "/data/fmc/pycharm_workspase/omni/.venv/lib/python2.7/site-packages/django/core/handlers/exception.py", line 39, in inner
    response = get_response(request)
  File "/data/fmc/pycharm_workspase/omni/.venv/lib/python2.7/site-packages/django/core/handlers/base.py", line 249, in _legacy_get_response
    response = self._get_response(request)
  File "/data/fmc/pycharm_workspase/omni/.venv/lib/python2.7/site-packages/django/core/handlers/base.py", line 187, in _get_response
    response = self.process_exception_by_middleware(e, request)
  File "/data/fmc/pycharm_workspase/omni/.venv/lib/python2.7/site-packages/django/core/handlers/base.py", line 185, in _get_response
    response = wrapped_callback(request, *callback_args, **callback_kwargs)
  File "/data/fmc/pycharm_workspase/omni/.venv/lib/python2.7/site-packages/django/views/decorators/csrf.py", line 58, in wrapped_view
    return view_func(*args, **kwargs)
  File "/data/fmc/pycharm_workspase/omni/.venv/lib/python2.7/site-packages/django/views/generic/base.py", line 68, in view
    return self.dispatch(request, *args, **kwargs)
  File "/data/fmc/pycharm_workspase/omni/.venv/lib/python2.7/site-packages/rest_framework/views.py", line 474, in dispatch
    response = self.handle_exception(exc)
  File "/data/fmc/pycharm_workspase/omni/.venv/lib/python2.7/site-packages/rest_framework/views.py", line 434, in handle_exception
    self.raise_uncaught_exception(exc)
  File "/data/fmc/pycharm_workspase/omni/.venv/lib/python2.7/site-packages/rest_framework/views.py", line 471, in dispatch
    response = handler(request, *args, **kwargs)
  File "/data/fmc/pycharm_workspase/omni/.venv/lib/python2.7/site-packages/rest_framework/generics.py", line 200, in get
    return self.list(request, *args, **kwargs)
  File "/data/fmc/pycharm_workspase/omni/.venv/lib/python2.7/site-packages/rest_framework/mixins.py", line 45, in list
    return self.get_paginated_response(serializer.data)
  File "/data/fmc/pycharm_workspase/omni/.venv/lib/python2.7/site-packages/rest_framework/serializers.py", line 701, in data
    ret = super(ListSerializer, self).data
  File "/data/fmc/pycharm_workspase/omni/.venv/lib/python2.7/site-packages/rest_framework/serializers.py", line 240, in data
    self._data = self.to_representation(self.instance)
  File "/data/fmc/pycharm_workspase/omni/.venv/lib/python2.7/site-packages/rest_framework/serializers.py", line 619, in to_representation
    self.child.to_representation(item) for item in iterable
  File "/data/fmc/pycharm_workspase/omni/.venv/lib/python2.7/site-packages/rest_framework/serializers.py", line 464, in to_representation
    attribute = field.get_attribute(instance)
  File "/data/fmc/pycharm_workspase/omni/.venv/lib/python2.7/site-packages/rest_framework/relations.py", line 491, in get_attribute
    relationship = get_attribute(instance, self.source_attrs)
  File "/data/fmc/pycharm_workspase/omni/.venv/lib/python2.7/site-packages/rest_framework/fields.py", line 83, in get_attribute
    instance = getattr(instance, attr)
  File "/data/fmc/pycharm_workspase/omni/.venv/lib/python2.7/site-packages/django/db/models/fields/related_descriptors.py", line 476, in __get__
    return self.related_manager_cls(instance)
  File "/data/fmc/pycharm_workspase/omni/.venv/lib/python2.7/site-packages/django/db/models/fields/related_descriptors.py", line 771, in __init__
    self.source_field = self.through._meta.get_field(self.source_field_name)
  File "/data/fmc/pycharm_workspase/omni/.venv/lib/python2.7/site-packages/django/db/models/options.py", line 619, in get_field
    raise FieldDoesNotExist('%s has no field named %r' % (self.object_name, field_name))
FieldDoesNotExist: UserGroupRelateAppIdModel has no field named None
ERROR    2016-10-09 20:10:27,940 django.request      [line 124 ] Internal Server Error: /restapi/arch/appids/
Traceback (most recent call last):
  File "/data/fmc/pycharm_workspase/omni/.venv/lib/python2.7/site-packages/django/core/handlers/exception.py", line 39, in inner
    response = get_response(request)
  File "/data/fmc/pycharm_workspase/omni/.venv/lib/python2.7/site-packages/django/core/handlers/base.py", line 249, in _legacy_get_response
    response = self._get_response(request)
  File "/data/fmc/pycharm_workspase/omni/.venv/lib/python2.7/site-packages/django/core/handlers/base.py", line 187, in _get_response
    response = self.process_exception_by_middleware(e, request)
  File "/data/fmc/pycharm_workspase/omni/.venv/lib/python2.7/site-packages/django/core/handlers/base.py", line 185, in _get_response
    response = wrapped_callback(request, *callback_args, **callback_kwargs)
  File "/data/fmc/pycharm_workspase/omni/.venv/lib/python2.7/site-packages/django/views/decorators/csrf.py", line 58, in wrapped_view
    return view_func(*args, **kwargs)
  File "/data/fmc/pycharm_workspase/omni/.venv/lib/python2.7/site-packages/django/views/generic/base.py", line 68, in view
    return self.dispatch(request, *args, **kwargs)
  File "/data/fmc/pycharm_workspase/omni/.venv/lib/python2.7/site-packages/rest_framework/views.py", line 474, in dispatch
    response = self.handle_exception(exc)
  File "/data/fmc/pycharm_workspase/omni/.venv/lib/python2.7/site-packages/rest_framework/views.py", line 434, in handle_exception
    self.raise_uncaught_exception(exc)
  File "/data/fmc/pycharm_workspase/omni/.venv/lib/python2.7/site-packages/rest_framework/views.py", line 471, in dispatch
    response = handler(request, *args, **kwargs)
  File "/data/fmc/pycharm_workspase/omni/.venv/lib/python2.7/site-packages/rest_framework/generics.py", line 200, in get
    return self.list(request, *args, **kwargs)
  File "/data/fmc/pycharm_workspase/omni/.venv/lib/python2.7/site-packages/rest_framework/mixins.py", line 45, in list
    return self.get_paginated_response(serializer.data)
  File "/data/fmc/pycharm_workspase/omni/.venv/lib/python2.7/site-packages/rest_framework/serializers.py", line 701, in data
    ret = super(ListSerializer, self).data
  File "/data/fmc/pycharm_workspase/omni/.venv/lib/python2.7/site-packages/rest_framework/serializers.py", line 240, in data
    self._data = self.to_representation(self.instance)
  File "/data/fmc/pycharm_workspase/omni/.venv/lib/python2.7/site-packages/rest_framework/serializers.py", line 619, in to_representation
    self.child.to_representation(item) for item in iterable
  File "/data/fmc/pycharm_workspase/omni/.venv/lib/python2.7/site-packages/rest_framework/serializers.py", line 464, in to_representation
    attribute = field.get_attribute(instance)
  File "/data/fmc/pycharm_workspase/omni/.venv/lib/python2.7/site-packages/rest_framework/relations.py", line 491, in get_attribute
    relationship = get_attribute(instance, self.source_attrs)
  File "/data/fmc/pycharm_workspase/omni/.venv/lib/python2.7/site-packages/rest_framework/fields.py", line 83, in get_attribute
    instance = getattr(instance, attr)
  File "/data/fmc/pycharm_workspase/omni/.venv/lib/python2.7/site-packages/django/db/models/fields/related_descriptors.py", line 476, in __get__
    return self.related_manager_cls(instance)
  File "/data/fmc/pycharm_workspase/omni/.venv/lib/python2.7/site-packages/django/db/models/fields/related_descriptors.py", line 771, in __init__
    self.source_field = self.through._meta.get_field(self.source_field_name)
  File "/data/fmc/pycharm_workspase/omni/.venv/lib/python2.7/site-packages/django/db/models/options.py", line 619, in get_field
    raise FieldDoesNotExist('%s has no field named %r' % (self.object_name, field_name))
FieldDoesNotExist: UserGroupRelateAppIdModel has no field named None
ERROR    2016-10-13 21:11:51,055 django.request      [line 124 ] Internal Server Error: /restapi/arch/projects/
Traceback (most recent call last):
  File "/data/fmc/pycharm_workspase/omni/.venv/lib/python2.7/site-packages/django/core/handlers/exception.py", line 39, in inner
    response = get_response(request)
  File "/data/fmc/pycharm_workspase/omni/.venv/lib/python2.7/site-packages/django/core/handlers/base.py", line 249, in _legacy_get_response
    response = self._get_response(request)
  File "/data/fmc/pycharm_workspase/omni/.venv/lib/python2.7/site-packages/django/core/handlers/base.py", line 187, in _get_response
    response = self.process_exception_by_middleware(e, request)
  File "/data/fmc/pycharm_workspase/omni/.venv/lib/python2.7/site-packages/django/core/handlers/base.py", line 185, in _get_response
    response = wrapped_callback(request, *callback_args, **callback_kwargs)
  File "/data/fmc/pycharm_workspase/omni/.venv/lib/python2.7/site-packages/django/views/decorators/csrf.py", line 58, in wrapped_view
    return view_func(*args, **kwargs)
  File "/data/fmc/pycharm_workspase/omni/.venv/lib/python2.7/site-packages/django/views/generic/base.py", line 68, in view
    return self.dispatch(request, *args, **kwargs)
  File "/data/fmc/pycharm_workspase/omni/.venv/lib/python2.7/site-packages/rest_framework/views.py", line 474, in dispatch
    response = self.handle_exception(exc)
  File "/data/fmc/pycharm_workspase/omni/.venv/lib/python2.7/site-packages/rest_framework/views.py", line 434, in handle_exception
    self.raise_uncaught_exception(exc)
  File "/data/fmc/pycharm_workspase/omni/.venv/lib/python2.7/site-packages/rest_framework/views.py", line 471, in dispatch
    response = handler(request, *args, **kwargs)
  File "/data/fmc/pycharm_workspase/omni/.venv/lib/python2.7/site-packages/rest_framework/generics.py", line 240, in get
    return self.list(request, *args, **kwargs)
  File "/data/fmc/pycharm_workspase/omni/omni/libs/django/view/mixin.py", line 82, in list
    response_data = self.get_response_data(request, serializer)
  File "/data/fmc/pycharm_workspase/omni/omni/libs/django/view/mixin.py", line 92, in get_response_data
    response_data = self.clean_relation_fields(request, serializer.data)
  File "/data/fmc/pycharm_workspase/omni/.venv/lib/python2.7/site-packages/rest_framework/serializers.py", line 701, in data
    ret = super(ListSerializer, self).data
  File "/data/fmc/pycharm_workspase/omni/.venv/lib/python2.7/site-packages/rest_framework/serializers.py", line 240, in data
    self._data = self.to_representation(self.instance)
  File "/data/fmc/pycharm_workspase/omni/.venv/lib/python2.7/site-packages/rest_framework/serializers.py", line 619, in to_representation
    self.child.to_representation(item) for item in iterable
  File "/data/fmc/pycharm_workspase/omni/.venv/lib/python2.7/site-packages/rest_framework/serializers.py", line 477, in to_representation
    ret[field.field_name] = field.to_representation(attribute)
  File "/data/fmc/pycharm_workspase/omni/.venv/lib/python2.7/site-packages/rest_framework/relations.py", line 497, in to_representation
    for value in iterable
TypeError: 'ProductModel' object is not iterable
ERROR    2016-10-13 21:11:51,194 django.request      [line 124 ] Internal Server Error: /restapi/arch/projects/
Traceback (most recent call last):
  File "/data/fmc/pycharm_workspase/omni/.venv/lib/python2.7/site-packages/django/core/handlers/exception.py", line 39, in inner
    response = get_response(request)
  File "/data/fmc/pycharm_workspase/omni/.venv/lib/python2.7/site-packages/django/core/handlers/base.py", line 249, in _legacy_get_response
    response = self._get_response(request)
  File "/data/fmc/pycharm_workspase/omni/.venv/lib/python2.7/site-packages/django/core/handlers/base.py", line 187, in _get_response
    response = self.process_exception_by_middleware(e, request)
  File "/data/fmc/pycharm_workspase/omni/.venv/lib/python2.7/site-packages/django/core/handlers/base.py", line 185, in _get_response
    response = wrapped_callback(request, *callback_args, **callback_kwargs)
  File "/data/fmc/pycharm_workspase/omni/.venv/lib/python2.7/site-packages/django/views/decorators/csrf.py", line 58, in wrapped_view
    return view_func(*args, **kwargs)
  File "/data/fmc/pycharm_workspase/omni/.venv/lib/python2.7/site-packages/django/views/generic/base.py", line 68, in view
    return self.dispatch(request, *args, **kwargs)
  File "/data/fmc/pycharm_workspase/omni/.venv/lib/python2.7/site-packages/rest_framework/views.py", line 474, in dispatch
    response = self.handle_exception(exc)
  File "/data/fmc/pycharm_workspase/omni/.venv/lib/python2.7/site-packages/rest_framework/views.py", line 434, in handle_exception
    self.raise_uncaught_exception(exc)
  File "/data/fmc/pycharm_workspase/omni/.venv/lib/python2.7/site-packages/rest_framework/views.py", line 471, in dispatch
    response = handler(request, *args, **kwargs)
  File "/data/fmc/pycharm_workspase/omni/.venv/lib/python2.7/site-packages/rest_framework/generics.py", line 240, in get
    return self.list(request, *args, **kwargs)
  File "/data/fmc/pycharm_workspase/omni/omni/libs/django/view/mixin.py", line 82, in list
    response_data = self.get_response_data(request, serializer)
  File "/data/fmc/pycharm_workspase/omni/omni/libs/django/view/mixin.py", line 92, in get_response_data
    response_data = self.clean_relation_fields(request, serializer.data)
  File "/data/fmc/pycharm_workspase/omni/.venv/lib/python2.7/site-packages/rest_framework/serializers.py", line 701, in data
    ret = super(ListSerializer, self).data
  File "/data/fmc/pycharm_workspase/omni/.venv/lib/python2.7/site-packages/rest_framework/serializers.py", line 240, in data
    self._data = self.to_representation(self.instance)
  File "/data/fmc/pycharm_workspase/omni/.venv/lib/python2.7/site-packages/rest_framework/serializers.py", line 619, in to_representation
    self.child.to_representation(item) for item in iterable
  File "/data/fmc/pycharm_workspase/omni/.venv/lib/python2.7/site-packages/rest_framework/serializers.py", line 477, in to_representation
    ret[field.field_name] = field.to_representation(attribute)
  File "/data/fmc/pycharm_workspase/omni/.venv/lib/python2.7/site-packages/rest_framework/relations.py", line 497, in to_representation
    for value in iterable
TypeError: 'ProductModel' object is not iterable
ERROR    2016-10-13 22:18:53,215 django.request      [line 124 ] Internal Server Error: /restapi/arch/projects/
Traceback (most recent call last):
  File "/data/fmc/pycharm_workspase/omni/.venv/lib/python2.7/site-packages/django/core/handlers/exception.py", line 39, in inner
    response = get_response(request)
  File "/data/fmc/pycharm_workspase/omni/.venv/lib/python2.7/site-packages/django/core/handlers/base.py", line 249, in _legacy_get_response
    response = self._get_response(request)
  File "/data/fmc/pycharm_workspase/omni/.venv/lib/python2.7/site-packages/django/core/handlers/base.py", line 187, in _get_response
    response = self.process_exception_by_middleware(e, request)
  File "/data/fmc/pycharm_workspase/omni/.venv/lib/python2.7/site-packages/django/core/handlers/base.py", line 185, in _get_response
    response = wrapped_callback(request, *callback_args, **callback_kwargs)
  File "/data/fmc/pycharm_workspase/omni/.venv/lib/python2.7/site-packages/django/views/decorators/csrf.py", line 58, in wrapped_view
    return view_func(*args, **kwargs)
  File "/data/fmc/pycharm_workspase/omni/.venv/lib/python2.7/site-packages/django/views/generic/base.py", line 68, in view
    return self.dispatch(request, *args, **kwargs)
  File "/data/fmc/pycharm_workspase/omni/.venv/lib/python2.7/site-packages/rest_framework/views.py", line 474, in dispatch
    response = self.handle_exception(exc)
  File "/data/fmc/pycharm_workspase/omni/.venv/lib/python2.7/site-packages/rest_framework/views.py", line 434, in handle_exception
    self.raise_uncaught_exception(exc)
  File "/data/fmc/pycharm_workspase/omni/.venv/lib/python2.7/site-packages/rest_framework/views.py", line 471, in dispatch
    response = handler(request, *args, **kwargs)
  File "/data/fmc/pycharm_workspase/omni/.venv/lib/python2.7/site-packages/rest_framework/generics.py", line 240, in get
    return self.list(request, *args, **kwargs)
  File "/data/fmc/pycharm_workspase/omni/omni/libs/django/view/mixin.py", line 82, in list
    response_data = self.get_response_data(request, serializer)
  File "/data/fmc/pycharm_workspase/omni/omni/libs/django/view/mixin.py", line 92, in get_response_data
    response_data = self.clean_relation_fields(request, serializer.data)
  File "/data/fmc/pycharm_workspase/omni/.venv/lib/python2.7/site-packages/rest_framework/serializers.py", line 701, in data
    ret = super(ListSerializer, self).data
  File "/data/fmc/pycharm_workspase/omni/.venv/lib/python2.7/site-packages/rest_framework/serializers.py", line 240, in data
    self._data = self.to_representation(self.instance)
  File "/data/fmc/pycharm_workspase/omni/.venv/lib/python2.7/site-packages/rest_framework/serializers.py", line 619, in to_representation
    self.child.to_representation(item) for item in iterable
  File "/data/fmc/pycharm_workspase/omni/.venv/lib/python2.7/site-packages/rest_framework/serializers.py", line 477, in to_representation
    ret[field.field_name] = field.to_representation(attribute)
  File "/data/fmc/pycharm_workspase/omni/.venv/lib/python2.7/site-packages/rest_framework/relations.py", line 497, in to_representation
    for value in iterable
TypeError: 'ProductModel' object is not iterable
ERROR    2016-10-13 23:27:30,658 django.request      [line 124 ] Internal Server Error: /restapi/arch/projects/
Traceback (most recent call last):
  File "/data/fmc/pycharm_workspase/omni/.venv/lib/python2.7/site-packages/django/core/handlers/exception.py", line 39, in inner
    response = get_response(request)
  File "/data/fmc/pycharm_workspase/omni/.venv/lib/python2.7/site-packages/django/core/handlers/base.py", line 249, in _legacy_get_response
    response = self._get_response(request)
  File "/data/fmc/pycharm_workspase/omni/.venv/lib/python2.7/site-packages/django/core/handlers/base.py", line 187, in _get_response
    response = self.process_exception_by_middleware(e, request)
  File "/data/fmc/pycharm_workspase/omni/.venv/lib/python2.7/site-packages/django/core/handlers/base.py", line 185, in _get_response
    response = wrapped_callback(request, *callback_args, **callback_kwargs)
  File "/data/fmc/pycharm_workspase/omni/.venv/lib/python2.7/site-packages/django/views/decorators/csrf.py", line 58, in wrapped_view
    return view_func(*args, **kwargs)
  File "/data/fmc/pycharm_workspase/omni/.venv/lib/python2.7/site-packages/django/views/generic/base.py", line 68, in view
    return self.dispatch(request, *args, **kwargs)
  File "/data/fmc/pycharm_workspase/omni/.venv/lib/python2.7/site-packages/rest_framework/views.py", line 474, in dispatch
    response = self.handle_exception(exc)
  File "/data/fmc/pycharm_workspase/omni/.venv/lib/python2.7/site-packages/rest_framework/views.py", line 434, in handle_exception
    self.raise_uncaught_exception(exc)
  File "/data/fmc/pycharm_workspase/omni/.venv/lib/python2.7/site-packages/rest_framework/views.py", line 471, in dispatch
    response = handler(request, *args, **kwargs)
  File "/data/fmc/pycharm_workspase/omni/.venv/lib/python2.7/site-packages/rest_framework/generics.py", line 240, in get
    return self.list(request, *args, **kwargs)
  File "/data/fmc/pycharm_workspase/omni/omni/libs/django/view/mixin.py", line 82, in list
    response_data = self.get_response_data(request, serializer)
  File "/data/fmc/pycharm_workspase/omni/omni/libs/django/view/mixin.py", line 92, in get_response_data
    response_data = self.clean_relation_fields(request, serializer.data)
  File "/data/fmc/pycharm_workspase/omni/.venv/lib/python2.7/site-packages/rest_framework/serializers.py", line 701, in data
    ret = super(ListSerializer, self).data
  File "/data/fmc/pycharm_workspase/omni/.venv/lib/python2.7/site-packages/rest_framework/serializers.py", line 240, in data
    self._data = self.to_representation(self.instance)
  File "/data/fmc/pycharm_workspase/omni/.venv/lib/python2.7/site-packages/rest_framework/serializers.py", line 619, in to_representation
    self.child.to_representation(item) for item in iterable
  File "/data/fmc/pycharm_workspase/omni/.venv/lib/python2.7/site-packages/rest_framework/serializers.py", line 477, in to_representation
    ret[field.field_name] = field.to_representation(attribute)
  File "/data/fmc/pycharm_workspase/omni/.venv/lib/python2.7/site-packages/rest_framework/relations.py", line 497, in to_representation
    for value in iterable
TypeError: 'ProductModel' object is not iterable
ERROR    2016-10-13 23:27:35,342 django.request      [line 124 ] Internal Server Error: /restapi/arch/appids/
Traceback (most recent call last):
  File "/data/fmc/pycharm_workspase/omni/.venv/lib/python2.7/site-packages/django/core/handlers/exception.py", line 39, in inner
    response = get_response(request)
  File "/data/fmc/pycharm_workspase/omni/.venv/lib/python2.7/site-packages/django/core/handlers/base.py", line 249, in _legacy_get_response
    response = self._get_response(request)
  File "/data/fmc/pycharm_workspase/omni/.venv/lib/python2.7/site-packages/django/core/handlers/base.py", line 187, in _get_response
    response = self.process_exception_by_middleware(e, request)
  File "/data/fmc/pycharm_workspase/omni/.venv/lib/python2.7/site-packages/django/core/handlers/base.py", line 185, in _get_response
    response = wrapped_callback(request, *callback_args, **callback_kwargs)
  File "/data/fmc/pycharm_workspase/omni/.venv/lib/python2.7/site-packages/django/views/decorators/csrf.py", line 58, in wrapped_view
    return view_func(*args, **kwargs)
  File "/data/fmc/pycharm_workspase/omni/.venv/lib/python2.7/site-packages/django/views/generic/base.py", line 68, in view
    return self.dispatch(request, *args, **kwargs)
  File "/data/fmc/pycharm_workspase/omni/.venv/lib/python2.7/site-packages/rest_framework/views.py", line 474, in dispatch
    response = self.handle_exception(exc)
  File "/data/fmc/pycharm_workspase/omni/.venv/lib/python2.7/site-packages/rest_framework/views.py", line 434, in handle_exception
    self.raise_uncaught_exception(exc)
  File "/data/fmc/pycharm_workspase/omni/.venv/lib/python2.7/site-packages/rest_framework/views.py", line 471, in dispatch
    response = handler(request, *args, **kwargs)
  File "/data/fmc/pycharm_workspase/omni/.venv/lib/python2.7/site-packages/rest_framework/generics.py", line 200, in get
    return self.list(request, *args, **kwargs)
  File "/data/fmc/pycharm_workspase/omni/omni/libs/django/view/mixin.py", line 82, in list
    response_data = self.get_response_data(request, serializer)
  File "/data/fmc/pycharm_workspase/omni/omni/libs/django/view/mixin.py", line 92, in get_response_data
    response_data = self.clean_relation_fields(request, serializer.data)
  File "/data/fmc/pycharm_workspase/omni/.venv/lib/python2.7/site-packages/rest_framework/serializers.py", line 701, in data
    ret = super(ListSerializer, self).data
  File "/data/fmc/pycharm_workspase/omni/.venv/lib/python2.7/site-packages/rest_framework/serializers.py", line 240, in data
    self._data = self.to_representation(self.instance)
  File "/data/fmc/pycharm_workspase/omni/.venv/lib/python2.7/site-packages/rest_framework/serializers.py", line 619, in to_representation
    self.child.to_representation(item) for item in iterable
  File "/data/fmc/pycharm_workspase/omni/.venv/lib/python2.7/site-packages/rest_framework/serializers.py", line 477, in to_representation
    ret[field.field_name] = field.to_representation(attribute)
  File "/data/fmc/pycharm_workspase/omni/.venv/lib/python2.7/site-packages/rest_framework/relations.py", line 497, in to_representation
    for value in iterable
TypeError: 'UserDepartmentModel' object is not iterable
ERROR    2016-10-14 00:16:39,162 django.request      [line 124 ] Internal Server Error: /restapi/arch/appids/
Traceback (most recent call last):
  File "/data/fmc/pycharm_workspase/omni/.venv/lib/python2.7/site-packages/django/core/handlers/exception.py", line 39, in inner
    response = get_response(request)
  File "/data/fmc/pycharm_workspase/omni/.venv/lib/python2.7/site-packages/django/core/handlers/base.py", line 249, in _legacy_get_response
    response = self._get_response(request)
  File "/data/fmc/pycharm_workspase/omni/.venv/lib/python2.7/site-packages/django/core/handlers/base.py", line 187, in _get_response
    response = self.process_exception_by_middleware(e, request)
  File "/data/fmc/pycharm_workspase/omni/.venv/lib/python2.7/site-packages/django/core/handlers/base.py", line 185, in _get_response
    response = wrapped_callback(request, *callback_args, **callback_kwargs)
  File "/data/fmc/pycharm_workspase/omni/.venv/lib/python2.7/site-packages/django/views/decorators/csrf.py", line 58, in wrapped_view
    return view_func(*args, **kwargs)
  File "/data/fmc/pycharm_workspase/omni/.venv/lib/python2.7/site-packages/django/views/generic/base.py", line 68, in view
    return self.dispatch(request, *args, **kwargs)
  File "/data/fmc/pycharm_workspase/omni/.venv/lib/python2.7/site-packages/rest_framework/views.py", line 474, in dispatch
    response = self.handle_exception(exc)
  File "/data/fmc/pycharm_workspase/omni/.venv/lib/python2.7/site-packages/rest_framework/views.py", line 434, in handle_exception
    self.raise_uncaught_exception(exc)
  File "/data/fmc/pycharm_workspase/omni/.venv/lib/python2.7/site-packages/rest_framework/views.py", line 471, in dispatch
    response = handler(request, *args, **kwargs)
  File "/data/fmc/pycharm_workspase/omni/.venv/lib/python2.7/site-packages/rest_framework/generics.py", line 200, in get
    return self.list(request, *args, **kwargs)
  File "/data/fmc/pycharm_workspase/omni/omni/libs/django/view/mixin.py", line 79, in list
    page = self.paginate_queryset(queryset)
  File "/data/fmc/pycharm_workspase/omni/.venv/lib/python2.7/site-packages/rest_framework/generics.py", line 172, in paginate_queryset
    return self.paginator.paginate_queryset(queryset, self.request, view=self)
  File "/data/fmc/pycharm_workspase/omni/omni/libs/django/view/pagination.py", line 23, in paginate_queryset
    return super(OffAblePageNumberPagination, self).paginate_queryset(queryset, request, view)
  File "/data/fmc/pycharm_workspase/omni/.venv/lib/python2.7/site-packages/rest_framework/pagination.py", line 222, in paginate_queryset
    return list(self.page)
  File "/data/fmc/pycharm_workspase/omni/.venv/lib/python2.7/site-packages/django/core/paginator.py", line 112, in __len__
    return len(self.object_list)
  File "/data/fmc/pycharm_workspase/omni/.venv/lib/python2.7/site-packages/django/db/models/query.py", line 238, in __len__
    self._fetch_all()
  File "/data/fmc/pycharm_workspase/omni/.venv/lib/python2.7/site-packages/django/db/models/query.py", line 1087, in _fetch_all
    self._result_cache = list(self.iterator())
  File "/data/fmc/pycharm_workspase/omni/.venv/lib/python2.7/site-packages/django/db/models/query.py", line 54, in __iter__
    results = compiler.execute_sql()
  File "/data/fmc/pycharm_workspase/omni/.venv/lib/python2.7/site-packages/django/db/models/sql/compiler.py", line 824, in execute_sql
    sql, params = self.as_sql()
  File "/data/fmc/pycharm_workspase/omni/.venv/lib/python2.7/site-packages/django/db/models/sql/compiler.py", line 369, in as_sql
    extra_select, order_by, group_by = self.pre_sql_setup()
  File "/data/fmc/pycharm_workspase/omni/.venv/lib/python2.7/site-packages/django/db/models/sql/compiler.py", line 46, in pre_sql_setup
    self.setup_query()
  File "/data/fmc/pycharm_workspase/omni/.venv/lib/python2.7/site-packages/django/db/models/sql/compiler.py", line 37, in setup_query
    self.select, self.klass_info, self.annotation_col_map = self.get_select()
  File "/data/fmc/pycharm_workspase/omni/.venv/lib/python2.7/site-packages/django/db/models/sql/compiler.py", line 213, in get_select
    related_klass_infos = self.get_related_selections(select)
  File "/data/fmc/pycharm_workspase/omni/.venv/lib/python2.7/site-packages/django/db/models/sql/compiler.py", line 749, in get_related_selections
    ', '.join(_get_field_choices()) or '(none)',
FieldError: Invalid field name(s) given in select_related: 'ops_user_group', 'dev_user_group'. Choices are: product, project, owner, dev_department
ERROR    2016-10-14 00:33:24,680 django.request      [line 124 ] Internal Server Error: /restapi/arch/appids/
Traceback (most recent call last):
  File "/data/fmc/pycharm_workspase/omni/.venv/lib/python2.7/site-packages/django/core/handlers/exception.py", line 39, in inner
    response = get_response(request)
  File "/data/fmc/pycharm_workspase/omni/.venv/lib/python2.7/site-packages/django/core/handlers/base.py", line 249, in _legacy_get_response
    response = self._get_response(request)
  File "/data/fmc/pycharm_workspase/omni/.venv/lib/python2.7/site-packages/django/core/handlers/base.py", line 187, in _get_response
    response = self.process_exception_by_middleware(e, request)
  File "/data/fmc/pycharm_workspase/omni/.venv/lib/python2.7/site-packages/django/core/handlers/base.py", line 185, in _get_response
    response = wrapped_callback(request, *callback_args, **callback_kwargs)
  File "/data/fmc/pycharm_workspase/omni/.venv/lib/python2.7/site-packages/django/views/decorators/csrf.py", line 58, in wrapped_view
    return view_func(*args, **kwargs)
  File "/data/fmc/pycharm_workspase/omni/.venv/lib/python2.7/site-packages/django/views/generic/base.py", line 68, in view
    return self.dispatch(request, *args, **kwargs)
  File "/data/fmc/pycharm_workspase/omni/.venv/lib/python2.7/site-packages/rest_framework/views.py", line 474, in dispatch
    response = self.handle_exception(exc)
  File "/data/fmc/pycharm_workspase/omni/.venv/lib/python2.7/site-packages/rest_framework/views.py", line 434, in handle_exception
    self.raise_uncaught_exception(exc)
  File "/data/fmc/pycharm_workspase/omni/.venv/lib/python2.7/site-packages/rest_framework/views.py", line 471, in dispatch
    response = handler(request, *args, **kwargs)
  File "/data/fmc/pycharm_workspase/omni/.venv/lib/python2.7/site-packages/rest_framework/generics.py", line 200, in get
    return self.list(request, *args, **kwargs)
  File "/data/fmc/pycharm_workspase/omni/omni/libs/django/view/mixin.py", line 82, in list
    response_data = self.get_response_data(request, serializer)
  File "/data/fmc/pycharm_workspase/omni/omni/libs/django/view/mixin.py", line 92, in get_response_data
    response_data = self.clean_relation_fields(request, serializer.data)
  File "/data/fmc/pycharm_workspase/omni/.venv/lib/python2.7/site-packages/rest_framework/serializers.py", line 701, in data
    ret = super(ListSerializer, self).data
  File "/data/fmc/pycharm_workspase/omni/.venv/lib/python2.7/site-packages/rest_framework/serializers.py", line 240, in data
    self._data = self.to_representation(self.instance)
  File "/data/fmc/pycharm_workspase/omni/.venv/lib/python2.7/site-packages/rest_framework/serializers.py", line 619, in to_representation
    self.child.to_representation(item) for item in iterable
  File "/data/fmc/pycharm_workspase/omni/.venv/lib/python2.7/site-packages/rest_framework/serializers.py", line 477, in to_representation
    ret[field.field_name] = field.to_representation(attribute)
  File "/data/fmc/pycharm_workspase/omni/omni/libs/django_rest_framework/relations.py", line 21, in to_representation
    return {field: value[field] for field in value._meta.fields}
  File "/data/fmc/pycharm_workspase/omni/omni/libs/django_rest_framework/relations.py", line 21, in <dictcomp>
    return {field: value[field] for field in value._meta.fields}
TypeError: 'UserDepartmentModel' object has no attribute '__getitem__'
